Workbook
Name LPI: 'Formula of Liquefaction'!$AE$2

Sheet Formula of Liquefaction
A1: Latitude | B1: Longitude | C1: Depth (z) | D1: Layer Thickness (z2) | E1: Total Unit Weight (y) | F1: N60 | G1: Fines Content (FC) | H1: Magnitude | I1: Peak Ground Acceleration (PGA) | J1: Gound Water Level (GWL) | K1: Pore Pressure (u) | L1: Total Stress (Ot) | M1: Effective Stress | N1: Cn | O1: N160 | P1: N160_2 | Q1: N160cs | R1: m | S1: Cn_final | T1: N160cs_final | U1: rd | V1: CSR | W1: MSFmax | X1: MSF | Y1: Ko | Z1: CRR7.5 | AA1: FS | AB1: Remarks | AC1: Severity (Fi) | AD1: Weighting Factor | AE1: LPI | AF1: Remarks
C2: 1.5 | D2: 1.5 | E2: 18 | F2: 6 | G2: 57.32 | H2: 7 | I2: 0.4 | J2: 1.1 | K2: =IF(C2<=J2, 0, (C2-J2)*9.81) -> 3.924 | L2: =IF(ROW()=2, C2*E2, L1 + (C2-C1)*E2) -> 27 | M2: =L2 - K2 -> 23.076 | N2: =MIN(1.7, (101.3 / M2)^0.5) -> 1.7 | O2: =F2 * N2 -> 10.2 | P2: =EXP(1.63 + (9.7/(G2+0.01)) - ((15.7/(G2+0.01))^2)) -> 5.6080347 | Q2: =O2 + P2 -> 15.808035 | R2: =0.784 - 0.0768 * SQRT(Q2) -> 0.47864843 | S2: =MIN(1.7, (101.3 / M2)^R2) -> 1.7 | T2: =(F2 * S2) + P2 -> 15.808035 | U2: =EXP((-1.012 - 1.126*SIN((C2/11.73)+5.133)) + (0.106 + 0.118*SIN((C2/11.28)+5.142))*H2) -> 0.99216797 | V2: =0.65 * I2 * (L2 / M2) * U2 -> 0.30182957 | W2: =MIN(2.2, 1.09 + (T2 / 31.5)^2) -> 1.3418458 | X2: =1 + (W2 - 1) * (8.64 * EXP(-H2/4) - 1.325) -> 1.0603039 | Y2: =MIN(1.1, 1 - MIN(0.3, 1 / (18.9 - 2.55 * SQRT(T2))) * LN(M2 / 101.3)) -> 1.1 | Z2: =EXP((T2/14.1) + (T2/126)^2 - (T2/23.6)^3 + (T2/25.4)^4 - 2.8) -> 0.1630612 | AA2: =IF(V2=0, "N/A", (Z2 * X2 * Y2) / V2) -> 0.63010351 | AB2: =IF(AA2>1, "NOT LIQUEFIABLE", "LIQUEFIABLE") -> LIQUEFIABLE | AC2: =IF(AA2<1, 1-AA2, 0) -> 0.36989649 | AD2: =IF(C2<=20, 10 - (0.5 * C2), 0) -> 9.25 | AE2: =AC2 * AD2 * D2 -> 5.1323138 | AF2: =IF(AE2<=0,"Very Low",IF(AND(AE2>0,AE2<=5),"Low",IF(AND(AE2>5,AE2<=15),"High","Very High"))) -> High
C3: 3 | D3: 1.5 | E3: 17 | F3: 6 | G3: 51.34 | H3: 7 | I3: 0.4 | J3: 1.1 | K3: =IF(C3<=J3, 0, (C3-J3)*9.81) -> 18.639 | L3: =IF(ROW()=2, C3*E3, L2 + (C3-C2)*E3) -> 52.5 | M3: =L3 - K3 -> 33.861 | N3: =MIN(1.7, (101.3 / M3)^0.5) -> 1.7 | O3: =F3 * N3 -> 10.2 | P3: =EXP(1.63 + (9.7/(G3+0.01)) - ((15.7/(G3+0.01))^2)) -> 5.6148775 | Q3: =O3 + P3 -> 15.814877 | R3: =0.784 - 0.0768 * SQRT(Q3) -> 0.47858235 | S3: =MIN(1.7, (101.3 / M3)^R3) -> 1.6895147 | T3: =(F3 * S3) + P3 -> 15.751965 | U3: =EXP((-1.012 - 1.126*SIN((C3/11.73)+5.133)) + (0.106 + 0.118*SIN((C3/11.28)+5.142))*H3) -> 0.97433785 | V3: =0.65 * I3 * (L3 / M3) * U3 -> 0.39277374 | W3: =MIN(2.2, 1.09 + (T3 / 31.5)^2) -> 1.3400624 | X3: =1 + (W3 - 1) * (8.64 * EXP(-H3/4) - 1.325) -> 1.0599893 | Y3: =MIN(1.1, 1 - MIN(0.3, 1 / (18.9 - 2.55 * SQRT(T3))) * LN(M3 / 101.3)) -> 1.1 | Z3: =EXP((T3/14.1) + (T3/126)^2 - (T3/23.6)^3 + (T3/25.4)^4 - 2.8) -> 0.16256971 | AA3: =IF(V3=0, "N/A", (Z3 * X3 * Y3) / V3) -> 0.4826045 | AB3: =IF(AA3>1, "NOT LIQUEFIABLE", "LIQUEFIABLE") -> LIQUEFIABLE | AC3: =IF(AA3<1, 1-AA3, 0) -> 0.5173955 | AD3: =IF(C3<=20, 10 - (0.5 * C3), 0) -> 8.5 | AE3: =AC3 * AD3 * D3 -> 6.5967926 | AF3: =IF(AE3<=0,"Very Low",IF(AND(AE3>0,AE3<=5),"Low",IF(AND(AE3>5,AE3<=15),"High","Very High"))) -> High
C4: 4.5 | D4: 1.5 | E4: 17.9 | F4: 9 | G4: 51.28 | H4: 7 | I4: 0.4 | J4: 1.1 | K4: =IF(C4<=J4, 0, (C4-J4)*9.81) -> 33.354 | L4: =IF(ROW()=2, C4*E4, L3 + (C4-C3)*E4) -> 79.35 | M4: =L4 - K4 -> 45.996 | N4: =MIN(1.7, (101.3 / M4)^0.5) -> 1.4840369 | O4: =F4 * N4 -> 13.356332 | P4: =EXP(1.63 + (9.7/(G4+0.01)) - ((15.7/(G4+0.01))^2)) -> 5.6148895 | Q4: =O4 + P4 -> 18.971221 | R4: =0.784 - 0.0768 * SQRT(Q4) -> 0.44949018 | S4: =MIN(1.7, (101.3 / M4)^R4) -> 1.4260193 | T4: =(F4 * S4) + P4 -> 18.449063 | U4: =EXP((-1.012 - 1.126*SIN((C4/11.73)+5.133)) + (0.106 + 0.118*SIN((C4/11.28)+5.142))*H4) -> 0.95382539 | V4: =0.65 * I4 * (L4 / M4) * U4 -> 0.42782789 | W4: =MIN(2.2, 1.09 + (T4 / 31.5)^2) -> 1.4330264 | X4: =1 + (W4 - 1) * (8.64 * EXP(-H4/4) - 1.325) -> 1.0763888 | Y4: =MIN(1.1, 1 - MIN(0.3, 1 / (18.9 - 2.55 * SQRT(T4))) * LN(M4 / 101.3)) -> 1.0993479 | Z4: =EXP((T4/14.1) + (T4/126)^2 - (T4/23.6)^3 + (T4/25.4)^4 - 2.8) -> 0.18833745 | AA4: =IF(V4=0, "N/A", (Z4 * X4 * Y4) / V4) -> 0.52092106 | AB4: =IF(AA4>1, "NOT LIQUEFIABLE", "LIQUEFIABLE") -> LIQUEFIABLE | AC4: =IF(AA4<1, 1-AA4, 0) -> 0.47907894 | AD4: =IF(C4<=20, 10 - (0.5 * C4), 0) -> 7.75 | AE4: =AC4 * AD4 * D4 -> 5.5692927 | AF4: =IF(AE4<=0,"Very Low",IF(AND(AE4>0,AE4<=5),"Low",IF(AND(AE4>5,AE4<=15),"High","Very High"))) -> High
C5: 6 | D5: 1.5 | E5: 18.3 | F5: 18 | G5: 55.75 | H5: 7 | I5: 0.4 | J5: 1.1 | K5: =IF(C5<=J5, 0, (C5-J5)*9.81) -> 48.069 | L5: =IF(ROW()=2, C5*E5, L4 + (C5-C4)*E5) -> 106.8 | M5: =L5 - K5 -> 58.731 | N5: =MIN(1.7, (101.3 / M5)^0.5) -> 1.3133214 | O5: =F5 * N5 -> 23.639785 | P5: =EXP(1.63 + (9.7/(G5+0.01)) - ((15.7/(G5+0.01))^2)) -> 5.6107345 | Q5: =O5 + P5 -> 29.25052 | R5: =0.784 - 0.0768 * SQRT(Q5) -> 0.3686368 | S5: =MIN(1.7, (101.3 / M5)^R5) -> 1.2225646 | T5: =(F5 * S5) + P5 -> 27.616898 | U5: =EXP((-1.012 - 1.126*SIN((C5/11.73)+5.133)) + (0.106 + 0.118*SIN((C5/11.28)+5.142))*H5) -> 0.93104429 | V5: =0.65 * I5 * (L5 / M5) * U5 -> 0.44019747 | W5: =MIN(2.2, 1.09 + (T5 / 31.5)^2) -> 1.8586501 | X5: =1 + (W5 - 1) * (8.64 * EXP(-H5/4) - 1.325) -> 1.1514718 | Y5: =MIN(1.1, 1 - MIN(0.3, 1 / (18.9 - 2.55 * SQRT(T5))) * LN(M5 / 101.3)) -> 1.0991252 | Z5: =EXP((T5/14.1) + (T5/126)^2 - (T5/23.6)^3 + (T5/25.4)^4 - 2.8) -> 0.36852819 | AA5: =IF(V5=0, "N/A", (Z5 * X5 * Y5) / V5) -> 1.0595553 | AB5: =IF(AA5>1, "NOT LIQUEFIABLE", "LIQUEFIABLE") -> NOT LIQUEFIABLE | AC5: =IF(AA5<1, 1-AA5, 0) -> 0 | AD5: =IF(C5<=20, 10 - (0.5 * C5), 0) -> 7 | AE5: =AC5 * AD5 * D5 -> 0 | AF5: =IF(AE5<=0,"Very Low",IF(AND(AE5>0,AE5<=5),"Low",IF(AND(AE5>5,AE5<=15),"High","Very High"))) -> Very Low
C6: 7.5 | D6: 1.5 | E6: 17.6 | F6: 11 | G6: 56.46 | H6: 7 | I6: 0.4 | J6: 1.1 | K6: =IF(C6<=J6, 0, (C6-J6)*9.81) -> 62.784 | L6: =IF(ROW()=2, C6*E6, L5 + (C6-C5)*E6) -> 133.2 | M6: =L6 - K6 -> 70.416 | N6: =MIN(1.7, (101.3 / M6)^0.5) -> 1.1994138 | O6: =F6 * N6 -> 13.193552 | P6: =EXP(1.63 + (9.7/(G6+0.01)) - ((15.7/(G6+0.01))^2)) -> 5.6095776 | Q6: =O6 + P6 -> 18.80313 | R6: =0.784 - 0.0768 * SQRT(Q6) -> 0.45097542 | S6: =MIN(1.7, (101.3 / M6)^R6) -> 1.1782195 | T6: =(F6 * S6) + P6 -> 18.569992 | U6: =EXP((-1.012 - 1.126*SIN((C6/11.73)+5.133)) + (0.106 + 0.118*SIN((C6/11.28)+5.142))*H6) -> 0.90643373 | V6: =0.65 * I6 * (L6 / M6) * U6 -> 0.44580228 | W6: =MIN(2.2, 1.09 + (T6 / 31.5)^2) -> 1.437538 | X6: =1 + (W6 - 1) * (8.64 * EXP(-H6/4) - 1.325) -> 1.0771847 | Y6: =MIN(1.1, 1 - MIN(0.3, 1 / (18.9 - 2.55 * SQRT(T6))) * LN(M6 / 101.3)) -> 1.0459679 | Z6: =EXP((T6/14.1) + (T6/126)^2 - (T6/23.6)^3 + (T6/25.4)^4 - 2.8) -> 0.18961722 | AA6: =IF(V6=0, "N/A", (Z6 * X6 * Y6) / V6) -> 0.47923002 | AB6: =IF(AA6>1, "NOT LIQUEFIABLE", "LIQUEFIABLE") -> LIQUEFIABLE | AC6: =IF(AA6<1, 1-AA6, 0) -> 0.52076998 | AD6: =IF(C6<=20, 10 - (0.5 * C6), 0) -> 6.25 | AE6: =AC6 * AD6 * D6 -> 4.8822186 | AF6: =IF(AE6<=0,"Very Low",IF(AND(AE6>0,AE6<=5),"Low",IF(AND(AE6>5,AE6<=15),"High","Very High"))) -> Low
C7: 9 | D7: 1.5 | E7: 18 | F7: 12 | G7: 55.52 | H7: 7 | I7: 0.4 | J7: 1.1 | K7: =IF(C7<=J7, 0, (C7-J7)*9.81) -> 77.499 | L7: =IF(ROW()=2, C7*E7, L6 + (C7-C6)*E7) -> 160.2 | M7: =L7 - K7 -> 82.701 | N7: =MIN(1.7, (101.3 / M7)^0.5) -> 1.1067495 | O7: =F7 * N7 -> 13.280994 | P7: =EXP(1.63 + (9.7/(G7+0.01)) - ((15.7/(G7+0.01))^2)) -> 5.6110848 | Q7: =O7 + P7 -> 18.892079 | R7: =0.784 - 0.0768 * SQRT(Q7) -> 0.45018865 | S7: =MIN(1.7, (101.3 / M7)^R7) -> 1.0956227 | T7: =(F7 * S7) + P7 -> 18.758557 | U7: =EXP((-1.012 - 1.126*SIN((C7/11.73)+5.133)) + (0.106 + 0.118*SIN((C7/11.28)+5.142))*H7) -> 0.88044424 | V7: =0.65 * I7 * (L7 / M7) * U7 -> 0.44343192 | W7: =MIN(2.2, 1.09 + (T7 / 31.5)^2) -> 1.4446319 | X7: =1 + (W7 - 1) * (8.64 * EXP(-H7/4) - 1.325) -> 1.0784361 | Y7: =MIN(1.1, 1 - MIN(0.3, 1 / (18.9 - 2.55 * SQRT(T7))) * LN(M7 / 101.3)) -> 1.0258228 | Z7: =EXP((T7/14.1) + (T7/126)^2 - (T7/23.6)^3 + (T7/25.4)^4 - 2.8) -> 0.19163913 | AA7: =IF(V7=0, "N/A", (Z7 * X7 * Y7) / V7) -> 0.47810577 | AB7: =IF(AA7>1, "NOT LIQUEFIABLE", "LIQUEFIABLE") -> LIQUEFIABLE | AC7: =IF(AA7<1, 1-AA7, 0) -> 0.52189423 | AD7: =IF(C7<=20, 10 - (0.5 * C7), 0) -> 5.5 | AE7: =AC7 * AD7 * D7 -> 4.3056274 | AF7: =IF(AE7<=0,"Very Low",IF(AND(AE7>0,AE7<=5),"Low",IF(AND(AE7>5,AE7<=15),"High","Very High"))) -> Low
C8: 10.5 | D8: 1.5 | E8: 18 | F8: 17 | G8: 52.11 | H8: 7 | I8: 0.4 | J8: 1.1 | K8: =IF(C8<=J8, 0, (C8-J8)*9.81) -> 92.214 | L8: =IF(ROW()=2, C8*E8, L7 + (C8-C7)*E8) -> 187.2 | M8: =L8 - K8 -> 94.986 | N8: =MIN(1.7, (101.3 / M8)^0.5) -> 1.0327018 | O8: =F8 * N8 -> 17.55593 | P8: =EXP(1.63 + (9.7/(G8+0.01)) - ((15.7/(G8+0.01))^2)) -> 5.614602 | Q8: =O8 + P8 -> 23.170532 | R8: =0.784 - 0.0768 * SQRT(Q8) -> 0.41431722 | S8: =MIN(1.7, (101.3 / M8)^R8) -> 1.0270228 | T8: =(F8 * S8) + P8 -> 23.07399 | U8: =EXP((-1.012 - 1.126*SIN((C8/11.73)+5.133)) + (0.106 + 0.118*SIN((C8/11.28)+5.142))*H8) -> 0.8535246 | V8: =0.65 * I8 * (L8 / M8) * U8 -> 0.43735655 | W8: =MIN(2.2, 1.09 + (T8 / 31.5)^2) -> 1.6265674 | X8: =1 + (W8 - 1) * (8.64 * EXP(-H8/4) - 1.325) -> 1.1105308 | Y8: =MIN(1.1, 1 - MIN(0.3, 1 / (18.9 - 2.55 * SQRT(T8))) * LN(M8 / 101.3)) -> 1.0096763 | Z8: =EXP((T8/14.1) + (T8/126)^2 - (T8/23.6)^3 + (T8/25.4)^4 - 2.8) -> 0.25067172 | AA8: =IF(V8=0, "N/A", (Z8 * X8 * Y8) / V8) -> 0.6426618 | AB8: =IF(AA8>1, "NOT LIQUEFIABLE", "LIQUEFIABLE") -> LIQUEFIABLE | AC8: =IF(AA8<1, 1-AA8, 0) -> 0.3573382 | AD8: =IF(C8<=20, 10 - (0.5 * C8), 0) -> 4.75 | AE8: =AC8 * AD8 * D8 -> 2.5460347 | AF8: =IF(AE8<=0,"Very Low",IF(AND(AE8>0,AE8<=5),"Low",IF(AND(AE8>5,AE8<=15),"High","Very High"))) -> Low
C9: 12 | D9: 1.5 | E9: 18.2 | F9: 20 | G9: 52.41 | H9: 7 | I9: 0.4 | J9: 1.1 | K9: =IF(C9<=J9, 0, (C9-J9)*9.81) -> 106.929 | L9: =IF(ROW()=2, C9*E9, L8 + (C9-C8)*E9) -> 214.5 | M9: =L9 - K9 -> 107.571 | N9: =MIN(1.7, (101.3 / M9)^0.5) -> 0.97041415 | O9: =F9 * N9 -> 19.408283 | P9: =EXP(1.63 + (9.7/(G9+0.01)) - ((15.7/(G9+0.01))^2)) -> 5.6144365 | Q9: =O9 + P9 -> 25.022719 | R9: =0.784 - 0.0768 * SQRT(Q9) -> 0.39982555 | S9: =MIN(1.7, (101.3 / M9)^R9) -> 0.97627068 | T9: =(F9 * S9) + P9 -> 25.13985 | U9: =EXP((-1.012 - 1.126*SIN((C9/11.73)+5.133)) + (0.106 + 0.118*SIN((C9/11.28)+5.142))*H9) -> 0.82611022 | V9: =0.65 * I9 * (L9 / M9) * U9 -> 0.42829542 | W9: =MIN(2.2, 1.09 + (T9 / 31.5)^2) -> 1.7269484 | X9: =1 + (W9 - 1) * (8.64 * EXP(-H9/4) - 1.325) -> 1.1282387 | Y9: =MIN(1.1, 1 - MIN(0.3, 1 / (18.9 - 2.55 * SQRT(T9))) * LN(M9 / 101.3)) -> 0.9901765 | Z9: =EXP((T9/14.1) + (T9/126)^2 - (T9/23.6)^3 + (T9/25.4)^4 - 2.8) -> 0.29335867 | AA9: =IF(V9=0, "N/A", (Z9 * X9 * Y9) / V9) -> 0.76518967 | AB9: =IF(AA9>1, "NOT LIQUEFIABLE", "LIQUEFIABLE") -> LIQUEFIABLE | AC9: =IF(AA9<1, 1-AA9, 0) -> 0.23481033 | AD9: =IF(C9<=20, 10 - (0.5 * C9), 0) -> 4 | AE9: =AC9 * AD9 * D9 -> 1.408862 | AF9: =IF(AE9<=0,"Very Low",IF(AND(AE9>0,AE9<=5),"Low",IF(AND(AE9>5,AE9<=15),"High","Very High"))) -> Low
C10: 13.5 | D10: 1.5 | E10: 16.9 | F10: 25 | G10: 56.38 | H10: 7 | I10: 0.4 | J10: 1.1 | K10: =IF(C10<=J10, 0, (C10-J10)*9.81) -> 121.644 | L10: =IF(ROW()=2, C10*E10, L9 + (C10-C9)*E10) -> 239.85 | M10: =L10 - K10 -> 118.206 | N10: =MIN(1.7, (101.3 / M10)^0.5) -> 0.92573133 | O10: =F10 * N10 -> 23.143283 | P10: =EXP(1.63 + (9.7/(G10+0.01)) - ((15.7/(G10+0.01))^2)) -> 5.6097135 | Q10: =O10 + P10 -> 28.752997 | R10: =0.784 - 0.0768 * SQRT(Q10) -> 0.37218442 | S10: =MIN(1.7, (101.3 / M10)^R10) -> 0.9441749 | T10: =(F10 * S10) + P10 -> 29.214086 | U10: =EXP((-1.012 - 1.126*SIN((C10/11.73)+5.133)) + (0.106 + 0.118*SIN((C10/11.28)+5.142))*H10) -> 0.79861349 | V10: =0.65 * I10 * (L10 / M10) * U10 -> 0.42131817 | W10: =MIN(2.2, 1.09 + (T10 / 31.5)^2) -> 1.9501288 | X10: =1 + (W10 - 1) * (8.64 * EXP(-H10/4) - 1.325) -> 1.1676093 | Y10: =MIN(1.1, 1 - MIN(0.3, 1 / (18.9 - 2.55 * SQRT(T10))) * LN(M10 / 101.3)) -> 0.9698387 | Z10: =EXP((T10/14.1) + (T10/126)^2 - (T10/23.6)^3 + (T10/25.4)^4 - 2.8) -> 0.43989446 | AA10: =IF(V10=0, "N/A", (Z10 * X10 * Y10) / V10) -> 1.1823208 | AB10: =IF(AA10>1, "NOT LIQUEFIABLE", "LIQUEFIABLE") -> NOT LIQUEFIABLE | AC10: =IF(AA10<1, 1-AA10, 0) -> 0 | AD10: =IF(C10<=20, 10 - (0.5 * C10), 0) -> 3.25 | AE10: =AC10 * AD10 * D10 -> 0 | AF10: =IF(AE10<=0,"Very Low",IF(AND(AE10>0,AE10<=5),"Low",IF(AND(AE10>5,AE10<=15),"High","Very High"))) -> Very Low
C11: 15 | D11: 1.5 | E11: 17.1 | F11: 27 | G11: 51.36 | H11: 7 | I11: 0.4 | J11: 1.1 | K11: =IF(C11<=J11, 0, (C11-J11)*9.81) -> 136.359 | L11: =IF(ROW()=2, C11*E11, L10 + (C11-C10)*E11) -> 265.5 | M11: =L11 - K11 -> 129.141 | N11: =MIN(1.7, (101.3 / M11)^0.5) -> 0.88567146 | O11: =F11 * N11 -> 23.913129 | P11: =EXP(1.63 + (9.7/(G11+0.01)) - ((15.7/(G11+0.01))^2)) -> 5.6148732 | Q11: =O11 + P11 -> 29.528003 | R11: =0.784 - 0.0768 * SQRT(Q11) -> 0.3666713 | S11: =MIN(1.7, (101.3 / M11)^R11) -> 0.91481397 | T11: =(F11 * S11) + P11 -> 30.31485 | U11: =EXP((-1.012 - 1.126*SIN((C11/11.73)+5.133)) + (0.106 + 0.118*SIN((C11/11.28)+5.142))*H11) -> 0.7714163 | V11: =0.65 * I11 * (L11 / M11) * U11 -> 0.41234672 | W11: =MIN(2.2, 1.09 + (T11 / 31.5)^2) -> 2.016168 | X11: =1 + (W11 - 1) * (8.64 * EXP(-H11/4) - 1.325) -> 1.179259 | Y11: =MIN(1.1, 1 - MIN(0.3, 1 / (18.9 - 2.55 * SQRT(T11))) * LN(M11 / 101.3)) -> 0.9500371 | Z11: =EXP((T11/14.1) + (T11/126)^2 - (T11/23.6)^3 + (T11/25.4)^4 - 2.8) -> 0.5053079 | AA11: =IF(V11=0, "N/A", (Z11 * X11 * Y11) / V11) -> 1.3729139 | AB11: =IF(AA11>1, "NOT LIQUEFIABLE", "LIQUEFIABLE") -> NOT LIQUEFIABLE | AC11: =IF(AA11<1, 1-AA11, 0) -> 0 | AD11: =IF(C11<=20, 10 - (0.5 * C11), 0) -> 2.5 | AE11: =AC11 * AD11 * D11 -> 0 | AF11: =IF(AE11<=0,"Very Low",IF(AND(AE11>0,AE11<=5),"Low",IF(AND(AE11>5,AE11<=15),"High","Very High"))) -> Very Low
AD12: TOTAL | AE12: =SUM(AE2:AE11) -> 30.441142 | AF12: =IF(AE12<=0,"Very Low",IF(AND(AE12>0,AE12<=5),"Low",IF(AND(AE12>5,AE12<=15),"High","Very High"))) -> Very High

Sheet Liquefaction & SBC
A1: No. of Boreholes | B1: Latitude | C1: Longitude | D1: Depth (z) | E1: Layer Thickness (z2) | F1: Total Unit Weight (y) | G1: N60 | H1: Fines Content (FC) | I1: Magnitude | J1: Peak Ground Acceleration (PGA) | K1: Gound Water Level (GWL) | L1: Soil Type | M1: Pore Pressure (u) | N1: Total Stress (Ot) | O1: Effective Stress | P1: Cn | Q1: N160 | R1: N160_2 | S1: N160cs | T1: m | U1: Cn_final | V1: N160cs_final | W1: rd | X1: CSR | Y1: MSFmax | Z1: MSF | AA1: Ko | AB1: CRR7.5 | AC1: FS | AD1: Remarks | AE1: Severity (Fi) | AF1: Weighting Factor | AG1: LPI | AH1: Remarks | AI1: Footing Width, B | AJ1: Depth of Footing, Df | AK1: Tolerable Settlement | AL1: Depth Factor, Fd | AM1: N | AN1: N_Design | AO1: Nc | AP1: SBC (qa) | AQ1: SBC (qa) NEW | AR1: SBC (qa) NEW (Final) | AS1: REMARKS
A2: 1 | B2: 15.279407 | C2: 120.5691 | D2: 1.5 | E2: 1.5 | F2: 21 | G2: 17 | H2: 51.21 | I2: 7 | J2: 0.4 | K2: 9 | L2: ML | M2: =IF(D2<=K2, 0, (D2-K2)*9.81) -> 0 | N2: =IF(ROW()=2, D2*F2, N1 + (D2-D1)*F2) -> 31.5 | O2: =N2 - M2 -> 31.5 | P2: =MIN(1.7, (101.3 / O2)^0.5) -> 1.7 | Q2: =G2 * P2 -> 28.9 | R2: =EXP(1.63 + (9.7/(H2+0.01)) - ((15.7/(H2+0.01))^2)) -> 5.6149018 | S2: =Q2 + R2 -> 34.514902 | T2: =0.784 - 0.0768 * SQRT(S2) -> 0.33280473 | U2: =MIN(1.7, (101.3 / O2)^T2) -> 1.475134 | V2: =(G2 * U2) + R2 -> 30.69218 | W2: =EXP((-1.012 - 1.126*SIN((D2/11.73)+5.133)) + (0.106 + 0.118*SIN((D2/11.28)+5.142))*I2) -> 0.99216797 | X2: =0.65 * J2 * (N2 / O2) * W2 -> 0.25796367 | Y2: =MIN(2.2, 1.09 + (V2 / 31.5)^2) -> 2.0393675 | Z2: =1 + (Y2 - 1) * (8.64 * EXP(-I2/4) - 1.325) -> 1.1833516 | AA2: =MIN(1.1, 1 - MIN(0.3, 1 / (18.9 - 2.55 * SQRT(V2))) * LN(O2 / 101.3)) -> 1.1 | AB2: =EXP((V2/14.1) + (V2/126)^2 - (V2/23.6)^3 + (V2/25.4)^4 - 2.8) -> 0.53174751 | AC2: =IF(X2=0, "N/A", MIN(5, (AB2 * Z2 * AA2) / X2)) -> 2.6832021 | AD2: =IF(AC2>1, "NOT LIQUEFIABLE", "LIQUEFIABLE") -> NOT LIQUEFIABLE | AE2: =IF(AC2<1, 1-AC2, 0) -> 0 | AF2: =IF(D2<=20, 10 - (0.5 * D2), 0) -> 9.25 | AG2: =AE2 * AF2 * E2 -> 0 | AH2: =IF(AG2<=0,"Very Low",IF(AND(AG2>0,AG2<=5),"Low",IF(AND(AG2>5,AG2<=15),"High","Very High"))) -> Very Low | AI2: 3 | AJ2: 1.5 | AK2: 25 | AL2: =MIN(1 + 0.33 * (AJ2 / AI2), 1.33) -> 1.165 | AM2: =AVERAGEIFS(G2:G11, D2:D11, ">" & AJ2, D2:D11, "<" & (AJ2 + AI2 + 1.5)) -> 19 | AN2: {=_xlfn.LET( _xlpm.Df, AJ2, _xlpm.B, AI2, _xlpm.LayerBottoms, D2:D11, _xlpm.LayerTops, D2:D11 - E2:E11, _xlpm.N_values, G2:G11, _xlpm.FilteredN, _xlfn._xlws.FILTER(_xlpm.N_values, (_xlpm.LayerBottoms > _xlpm.Df) * (_xlpm.LayerTops < (_xlpm.Df + 2*_xlpm.B))), _xlpm.i, _xlfn.SEQUENCE(ROWS(_xlpm.FilteredN)), SUM(_xlpm.FilteredN / _xlpm.i^2) / SUM(1 / _xlpm.i^2) )} -> 18.697561 | AO2: =MIN(6 * (1 + 0.2 * (AJ2 / AI2)), 9) -> 6.6 | AP2: =IF(AI2<=1.2,12*AM2*AL2*(AK2/25.4),8*AM2*((3.28*AI2+1)/(3.28*AI2))^2*AL2*(AK2/25.4)) -> 211.51646 | AQ2: {=_xlfn.LET( _xlpm.Df, AJ2, _xlpm.B, AI2, _xlpm.Settlement, AK2, _xlpm.NMeyerhof, AM2, _xlpm.NDesign, AN2, _xlpm.Nc, AO2, _xlpm.Fd, AL2, _xlpm.LayerBottoms, D2:D11, _xlpm.LayerThickness, E2:E11, _xlpm.USCS, L2:L11, _xlpm.LayerTops, _xlpm.LayerBottoms - _xlpm.LayerThickness, _xlpm.Overlap, (_xlpm.LayerBottoms > _xlpm.Df) * (_xlpm.LayerTops < (_xlpm.Df + 2*_xlpm.B)), _xlpm.FilteredUSCS, _xlfn._xlws.FILTER(_xlpm.USCS, _xlpm.Overlap, "None"), _xlpm.TotalLayers, ROWS(_xlpm.FilteredUSCS), _xlpm.CohesiveCount, SUM(--(ISNUMBER(MATCH(_xlpm.FilteredUSCS, {"CH","MH","CL","ML","OH","OL"}, 0)))), _xlpm.CohesionlessCount, SUM(--(ISNUMBER(MATCH(_xlpm.FilteredUSCS, {"GW","GP","GM","GC","SW","SP","SM","SC"}, 0)))), _xlpm.ZoneType, IF(INDEX(_xlpm.FilteredUSCS,1)="None", "No Soil", IF(_xlpm.CohesiveCount = _xlpm.TotalLayers, "Cohesive", IF(_xlpm.CohesionlessCount = _xlpm.TotalLayers, "Cohesionless", "Mixed"))), IF(_xlpm.ZoneType = "Cohesive", 2 * _xlpm.NDesign * _xlpm.Nc, IF(_xlpm.ZoneType = "Cohesionless", IF(_xlpm.B <= 1.2, 12 * _xlpm.NMeyerhof * _xlpm.Fd * (_xlpm.Settlement / 25.4), 8 * _xlpm.NMeyerhof * ((3.28 * _xlpm.B + 1) / (3.28 * _xlpm.B))^2 * _xlpm.Fd * (_xlpm.Settlement / 25.4) ), "Mixed Zone - Needs Manual Analysis" ) ) )} -> Mixed Zone - Needs Manual Analysis | AR2: {=_xlfn.LET( _xlpm.Df, AJ2, _xlpm.B, AI2, _xlpm.Settlement, AK2, _xlpm.NMeyerhof, AM2, _xlpm.NDesign, AN2, _xlpm.Nc, AO2, _xlpm.Fd, AL2, _xlpm.LayerBottoms, D2:D11, _xlpm.LayerThickness, E2:E11, _xlpm.USCS, L2:L11, _xlpm.LayerTops, _xlpm.LayerBottoms - _xlpm.LayerThickness, _xlpm.Overlap, (_xlpm.LayerBottoms > _xlpm.Df) * (_xlpm.LayerTops < (_xlpm.Df + 2*_xlpm.B)), _xlpm.FilteredUSCS, _xlfn._xlws.FILTER(_xlpm.USCS, _xlpm.Overlap, "None"), _xlpm.TotalLayers, ROWS(_xlpm.FilteredUSCS), _xlpm.CohesiveCount, SUM(--(ISNUMBER(MATCH(_xlpm.FilteredUSCS, {"CH","MH","CL","ML","OH","OL"}, 0)))), _xlpm.CohesionlessCount, SUM(--(ISNUMBER(MATCH(_xlpm.FilteredUSCS, {"GW","GP","GM","GC","SW","SP","SM","SC"}, 0)))), _xlpm.ZoneType, IF(INDEX(_xlpm.FilteredUSCS,1)="None", "No Soil", IF(_xlpm.CohesiveCount = _xlpm.TotalLayers, "Cohesive", IF(_xlpm.CohesionlessCount = _xlpm.TotalLayers, "Cohesionless", "Mixed"))), _xlpm.Qa_Cohesive, 2 * _xlpm.NDesign * _xlpm.Nc, _xlpm.Qa_Cohesionless, IF(_xlpm.B <= 1.2, 12 * _xlpm.NMeyerhof * _xlpm.Fd * (_xlpm.Settlement / 25.4), 8 * _xlpm.NMeyerhof * ((3.28 * _xlpm.B + 1) / (3.28 * _xlpm.B))^2 * _xlpm.Fd * (_xlpm.Settlement / 25.4)), IF(_xlpm.ZoneType = "Cohesive", _xlpm.Qa_Cohesive, IF(_xlpm.ZoneType = "Cohesionless", _xlpm.Qa_Cohesionless, IF(_xlpm.ZoneType = "Mixed", MIN(_xlpm.Qa_Cohesive, _xlpm.Qa_Cohesionless), "Invalid Data" ) ) ) )} -> 211.51646 | AS2: {=_xlfn.LET( _xlpm.Df, AJ2, _xlpm.B, AI2, _xlpm.Settlement, AK2, _xlpm.NMeyerhof, AM2, _xlpm.NDesign, AN2, _xlpm.Nc, AO2, _xlpm.Fd, AL2, _xlpm.LayerBottoms, D2:D11, _xlpm.LayerThickness, E2:E11, _xlpm.Material, L2:L11, _xlpm.LayerTops, _xlpm.LayerBottoms - _xlpm.LayerThickness, _xlpm.Overlap, (_xlpm.LayerBottoms > _xlpm.Df) * (_xlpm.LayerTops < (_xlpm.Df + 2*_xlpm.B)), _xlpm.FilteredMat, _xlfn._xlws.FILTER(_xlpm.Material, _xlpm.Overlap, "None"), _xlpm.TotalLayers, ROWS(_xlpm.FilteredMat), _xlpm.RockCount, SUM(--(ISNUMBER(MATCH(_xlpm.FilteredMat, {"Sandstone","Basalt","Cobblestone","Cobble Stone","Coring","Tuff"}, 0)))), _xlpm.CohesiveCount, SUM(--(ISNUMBER(MATCH(_xlpm.FilteredMat, {"CH","MH","CL","ML","OH","OL","Silty Tuff"}, 0)))), _xlpm.CohesionlessCount, SUM(--(ISNUMBER(MATCH(_xlpm.FilteredMat, {"GW","GP","GM","GC","SW","SP","SM","SC","Gravel"}, 0)))), _xlpm.ZoneType, IF(INDEX(_xlpm.FilteredMat,1)="None", "No Soil", IF(_xlpm.RockCount > 0, "Rock", IF(_xlpm.CohesiveCount = _xlpm.TotalLayers, "Cohesive", IF(_xlpm.CohesionlessCount = _xlpm.TotalLayers, "Cohesionless", "Mixed" ) ) ) ), _xlpm.Qa_Cohesive, 2 * _xlpm.NDesign * _xlpm.Nc, _xlpm.Qa_Cohesionless, IF(_xlpm.B <= 1.2, 12 * _xlpm.NMeyerhof * _xlpm.Fd * (_xlpm.Settlement / 25.4), 8 * _xlpm.NMeyerhof * ((3.28 * _xlpm.B + 1) / (3.28 * _xlpm.B))^2 * _xlpm.Fd * (_xlpm.Settlement / 25.4)), IF(_xlpm.ZoneType = "Rock", "N/A - Rock/Cobble Detected (Use Rock Mechanics)", IF(_xlpm.ZoneType = "Cohesive", _xlpm.Qa_Cohesive, IF(_xlpm.ZoneType = "Cohesionless", _xlpm.Qa_Cohesionless, IF(_xlpm.ZoneType = "Mixed", MIN(_xlpm.Qa_Cohesive, _xlpm.Qa_Cohesionless), "Invalid Data" ) ) ) ) )} -> 211.51646
B3: 15.279407 | C3: 120.5691 | D3: =D2+1.5 -> 3 | E3: 1.5 | F3: 21 | G3: 17 | H3: 51.21 | I3: 7 | J3: 0.4 | K3: 9 | L3: ML | M3: =IF(D3<=K3, 0, (D3-K3)*9.81) -> 0 | N3: =IF(ROW()=2, D3*F3, N2 + (D3-D2)*F3) -> 63 | O3: =N3 - M3 -> 63 | P3: =MIN(1.7, (101.3 / O3)^0.5) -> 1.2680444 | Q3: =G3 * P3 -> 21.556754 | R3: =EXP(1.63 + (9.7/(H3+0.01)) - ((15.7/(H3+0.01))^2)) -> 5.6149018 | S3: =Q3 + R3 -> 27.171656 | T3: =0.784 - 0.0768 * SQRT(S3) -> 0.38366895 | U3: =MIN(1.7, (101.3 / O3)^T3) -> 1.1998832 | V3: =(G3 * U3) + R3 -> 26.012916 | W3: =EXP((-1.012 - 1.126*SIN((D3/11.73)+5.133)) + (0.106 + 0.118*SIN((D3/11.28)+5.142))*I3) -> 0.97433785 | X3: =0.65 * J3 * (N3 / O3) * W3 -> 0.25332784 | Y3: =MIN(2.2, 1.09 + (V3 / 31.5)^2) -> 1.771957 | Z3: =1 + (Y3 - 1) * (8.64 * EXP(-I3/4) - 1.325) -> 1.1361785 | AA3: =MIN(1.1, 1 - MIN(0.3, 1 / (18.9 - 2.55 * SQRT(V3))) * LN(O3 / 101.3)) -> 1.0805785 | AB3: =EXP((V3/14.1) + (V3/126)^2 - (V3/23.6)^3 + (V3/25.4)^4 - 2.8) -> 0.31613897 | AC3: =IF(X3=0, "N/A", (AB3 * Z3 * AA3) / X3) -> 1.5321385 | AD3: =IF(AC3>1, "NOT LIQUEFIABLE", "LIQUEFIABLE") -> NOT LIQUEFIABLE | AE3: =IF(AC3<1, 1-AC3, 0) -> 0 | AF3: =IF(D3<=20, 10 - (0.5 * D3), 0) -> 8.5 | AG3: =AE3 * AF3 * E3 -> 0 | AH3: =IF(AG3<=0,"Very Low",IF(AND(AG3>0,AG3<=5),"Low",IF(AND(AG3>5,AG3<=15),"High","Very High"))) -> Very Low
B4: 15.279407 | C4: 120.5691 | D4: =D3+1.5 -> 4.5 | E4: 1.5 | F4: 20 | G4: 21 | H4: 25.01 | I4: 7 | J4: 0.4 | K4: 9 | L4: SM | M4: =IF(D4<=K4, 0, (D4-K4)*9.81) -> 0 | N4: =IF(ROW()=2, D4*F4, N3 + (D4-D3)*F4) -> 93 | O4: =N4 - M4 -> 93 | P4: =MIN(1.7, (101.3 / O4)^0.5) -> 1.0436701 | Q4: =G4 * P4 -> 21.917072 | R4: =EXP(1.63 + (9.7/(H4+0.01)) - ((15.7/(H4+0.01))^2)) -> 5.073019 | S4: =Q4 + R4 -> 26.990091 | T4: =0.784 - 0.0768 * SQRT(S4) -> 0.38500873 | U4: =MIN(1.7, (101.3 / O4)^T4) -> 1.0334608 | V4: =(G4 * U4) + R4 -> 26.775697 | W4: =EXP((-1.012 - 1.126*SIN((D4/11.73)+5.133)) + (0.106 + 0.118*SIN((D4/11.28)+5.142))*I4) -> 0.95382539 | X4: =0.65 * J4 * (N4 / O4) * W4 -> 0.2479946 | Y4: =MIN(2.2, 1.09 + (V4 / 31.5)^2) -> 1.8125376 | Z4: =1 + (Y4 - 1) * (8.64 * EXP(-I4/4) - 1.325) -> 1.1433372 | AA4: =MIN(1.1, 1 - MIN(0.3, 1 / (18.9 - 2.55 * SQRT(V4))) * LN(O4 / 101.3)) -> 1.0149847 | AB4: =EXP((V4/14.1) + (V4/126)^2 - (V4/23.6)^3 + (V4/25.4)^4 - 2.8) -> 0.33911545 | AC4: =IF(X4=0, "N/A", (AB4 * Z4 * AA4) / X4) -> 1.586862 | AD4: =IF(AC4>1, "NOT LIQUEFIABLE", "LIQUEFIABLE") -> NOT LIQUEFIABLE | AE4: =IF(AC4<1, 1-AC4, 0) -> 0 | AF4: =IF(D4<=20, 10 - (0.5 * D4), 0) -> 7.75 | AG4: =AE4 * AF4 * E4 -> 0 | AH4: =IF(AG4<=0,"Very Low",IF(AND(AG4>0,AG4<=5),"Low",IF(AND(AG4>5,AG4<=15),"High","Very High"))) -> Very Low
B5: 15.279407 | C5: 120.5691 | D5: =D4+1.5 -> 6 | E5: 1.5 | F5: 20 | G5: 23 | H5: 24.31 | I5: 7 | J5: 0.4 | K5: 9 | L5: SM | M5: =IF(D5<=K5, 0, (D5-K5)*9.81) -> 0 | N5: =IF(ROW()=2, D5*F5, N4 + (D5-D4)*F5) -> 123 | O5: =N5 - M5 -> 123 | P5: =MIN(1.7, (101.3 / O5)^0.5) -> 0.90751156 | Q5: =G5 * P5 -> 20.872766 | R5: =EXP(1.63 + (9.7/(H5+0.01)) - ((15.7/(H5+0.01))^2)) -> 5.0133381 | S5: =Q5 + R5 -> 25.886104 | T5: =0.784 - 0.0768 * SQRT(S5) -> 0.39325398 | U5: =MIN(1.7, (101.3 / O5)^T5) -> 0.9265106 | V5: =(G5 * U5) + R5 -> 26.323082 | W5: =EXP((-1.012 - 1.126*SIN((D5/11.73)+5.133)) + (0.106 + 0.118*SIN((D5/11.28)+5.142))*I5) -> 0.93104429 | X5: =0.65 * J5 * (N5 / O5) * W5 -> 0.24207152 | Y5: =MIN(2.2, 1.09 + (V5 / 31.5)^2) -> 1.7883166 | Z5: =1 + (Y5 - 1) * (8.64 * EXP(-I5/4) - 1.325) -> 1.1390645 | AA5: =MIN(1.1, 1 - MIN(0.3, 1 / (18.9 - 2.55 * SQRT(V5))) * LN(O5 / 101.3)) -> 0.96663243 | AB5: =EXP((V5/14.1) + (V5/126)^2 - (V5/23.6)^3 + (V5/25.4)^4 - 2.8) -> 0.32510201 | AC5: =IF(X5=0, "N/A", (AB5 * Z5 * AA5) / X5) -> 1.4787189 | AD5: =IF(AC5>1, "NOT LIQUEFIABLE", "LIQUEFIABLE") -> NOT LIQUEFIABLE | AE5: =IF(AC5<1, 1-AC5, 0) -> 0 | AF5: =IF(D5<=20, 10 - (0.5 * D5), 0) -> 7 | AG5: =AE5 * AF5 * E5 -> 0 | AH5: =IF(AG5<=0,"Very Low",IF(AND(AG5>0,AG5<=5),"Low",IF(AND(AG5>5,AG5<=15),"High","Very High"))) -> Very Low
B6: 15.279407 | C6: 120.5691 | D6: =D5+1.5 -> 7.5 | E6: 1.5 | F6: 20 | G6: 29 | H6: 17.46 | I6: 7 | J6: 0.4 | K6: 9 | L6: SM | M6: =IF(D6<=K6, 0, (D6-K6)*9.81) -> 0 | N6: =IF(ROW()=2, D6*F6, N5 + (D6-D5)*F6) -> 153 | O6: =N6 - M6 -> 153 | P6: =MIN(1.7, (101.3 / O6)^0.5) -> 0.81369005 | Q6: =G6 * P6 -> 23.597012 | R6: =EXP(1.63 + (9.7/(H6+0.01)) - ((15.7/(H6+0.01))^2)) -> 3.9653955 | S6: =Q6 + R6 -> 27.562407 | T6: =0.784 - 0.0768 * SQRT(S6) -> 0.38080068 | U6: =MIN(1.7, (101.3 / O6)^T6) -> 0.85468377 | V6: =(G6 * U6) + R6 -> 28.751225 | W6: =EXP((-1.012 - 1.126*SIN((D6/11.73)+5.133)) + (0.106 + 0.118*SIN((D6/11.28)+5.142))*I6) -> 0.90643373 | X6: =0.65 * J6 * (N6 / O6) * W6 -> 0.23567277 | Y6: =MIN(2.2, 1.09 + (V6 / 31.5)^2) -> 1.9230894 | Z6: =1 + (Y6 - 1) * (8.64 * EXP(-I6/4) - 1.325) -> 1.1628393 | AA6: =MIN(1.1, 1 - MIN(0.3, 1 / (18.9 - 2.55 * SQRT(V6))) * LN(O6 / 101.3)) -> 0.92110909 | AB6: =EXP((V6/14.1) + (V6/126)^2 - (V6/23.6)^3 + (V6/25.4)^4 - 2.8) -> 0.41673931 | AC6: =IF(X6=0, "N/A", (AB6 * Z6 * AA6) / X6) -> 1.8940256 | AD6: =IF(AC6>1, "NOT LIQUEFIABLE", "LIQUEFIABLE") -> NOT LIQUEFIABLE | AE6: =IF(AC6<1, 1-AC6, 0) -> 0 | AF6: =IF(D6<=20, 10 - (0.5 * D6), 0) -> 6.25 | AG6: =AE6 * AF6 * E6 -> 0 | AH6: =IF(AG6<=0,"Very Low",IF(AND(AG6>0,AG6<=5),"Low",IF(AND(AG6>5,AG6<=15),"High","Very High"))) -> Very Low
B7: 15.279407 | C7: 120.5691 | D7: =D6+1.5 -> 9 | E7: 1.5 | F7: 21 | G7: 35 | H7: 34.46 | I7: 7 | J7: 0.4 | K7: 9 | L7: SM | M7: =IF(D7<=K7, 0, (D7-K7)*9.81) -> 0 | N7: =IF(ROW()=2, D7*F7, N6 + (D7-D6)*F7) -> 184.5 | O7: =N7 - M7 -> 184.5 | P7: =MIN(1.7, (101.3 / O7)^0.5) -> 0.74098009 | Q7: =G7 * P7 -> 25.934303 | R7: =EXP(1.63 + (9.7/(H7+0.01)) - ((15.7/(H7+0.01))^2)) -> 5.4956262 | S7: =Q7 + R7 -> 31.429929 | T7: =0.784 - 0.0768 * SQRT(S7) -> 0.35344075 | U7: =MIN(1.7, (101.3 / O7)^T7) -> 0.80903749 | V7: =(G7 * U7) + R7 -> 33.811939 | W7: =EXP((-1.012 - 1.126*SIN((D7/11.73)+5.133)) + (0.106 + 0.118*SIN((D7/11.28)+5.142))*I7) -> 0.88044424 | X7: =0.65 * J7 * (N7 / O7) * W7 -> 0.2289155 | Y7: =MIN(2.2, 1.09 + (V7 / 31.5)^2) -> 2.2 | Z7: =1 + (Y7 - 1) * (8.64 * EXP(-I7/4) - 1.325) -> 1.2116882 | AA7: =MIN(1.1, 1 - MIN(0.3, 1 / (18.9 - 2.55 * SQRT(V7))) * LN(O7 / 101.3)) -> 0.85276865 | AB7: =EXP((V7/14.1) + (V7/126)^2 - (V7/23.6)^3 + (V7/25.4)^4 - 2.8) -> 0.8774598 | AC7: =IF(X7=0, "N/A", (AB7 * Z7 * AA7) / X7) -> 3.96072 | AD7: =IF(AC7>1, "NOT LIQUEFIABLE", "LIQUEFIABLE") -> NOT LIQUEFIABLE | AE7: =IF(AC7<1, 1-AC7, 0) -> 0 | AF7: =IF(D7<=20, 10 - (0.5 * D7), 0) -> 5.5 | AG7: =AE7 * AF7 * E7 -> 0 | AH7: =IF(AG7<=0,"Very Low",IF(AND(AG7>0,AG7<=5),"Low",IF(AND(AG7>5,AG7<=15),"High","Very High"))) -> Very Low
B8: 15.279407 | C8: 120.5691 | D8: =D7+1.5 -> 10.5 | E8: 1.5 | F8: 21 | G8: 41 | H8: 28.25 | I8: 7 | J8: 0.4 | K8: 9 | L8: SM | M8: =IF(D8<=K8, 0, (D8-K8)*9.81) -> 14.715 | N8: =IF(ROW()=2, D8*F8, N7 + (D8-D7)*F8) -> 216 | O8: =N8 - M8 -> 201.285 | P8: =MIN(1.7, (101.3 / O8)^0.5) -> 0.70941279 | Q8: =G8 * P8 -> 29.085925 | R8: =EXP(1.63 + (9.7/(H8+0.01)) - ((15.7/(H8+0.01))^2)) -> 5.283556 | S8: =Q8 + R8 -> 34.369481 | T8: =0.784 - 0.0768 * SQRT(S8) -> 0.33375624 | U8: =MIN(1.7, (101.3 / O8)^T8) -> 0.79519425 | V8: =(G8 * U8) + R8 -> 37.88652 | W8: =EXP((-1.012 - 1.126*SIN((D8/11.73)+5.133)) + (0.106 + 0.118*SIN((D8/11.28)+5.142))*I8) -> 0.8535246 | X8: =0.65 * J8 * (N8 / O8) * W8 -> 0.23813966 | Y8: =MIN(2.2, 1.09 + (V8 / 31.5)^2) -> 2.2 | Z8: =1 + (Y8 - 1) * (8.64 * EXP(-I8/4) - 1.325) -> 1.2116882 | AA8: =MIN(1.1, 1 - MIN(0.3, 1 / (18.9 - 2.55 * SQRT(V8))) * LN(O8 / 101.3)) -> 0.79400938 | AB8: =EXP((V8/14.1) + (V8/126)^2 - (V8/23.6)^3 + (V8/25.4)^4 - 2.8) -> 2.2035626 | AC8: =IF(X8=0, "N/A", (AB8 * Z8 * AA8) / X8) -> 8.9024631 | AD8: =IF(AC8>1, "NOT LIQUEFIABLE", "LIQUEFIABLE") -> NOT LIQUEFIABLE | AE8: =IF(AC8<1, 1-AC8, 0) -> 0 | AF8: =IF(D8<=20, 10 - (0.5 * D8), 0) -> 4.75 | AG8: =AE8 * AF8 * E8 -> 0 | AH8: =IF(AG8<=0,"Very Low",IF(AND(AG8>0,AG8<=5),"Low",IF(AND(AG8>5,AG8<=15),"High","Very High"))) -> Very Low
B9: 15.279407 | C9: 120.5691 | D9: =D8+1.5 -> 12 | E9: 1.5 | F9: 21 | G9: 46 | H9: 31.13 | I9: 7 | J9: 0.4 | K9: 9 | L9: SM | M9: =IF(D9<=K9, 0, (D9-K9)*9.81) -> 29.43 | N9: =IF(ROW()=2, D9*F9, N8 + (D9-D8)*F9) -> 247.5 | O9: =N9 - M9 -> 218.07 | P9: =MIN(1.7, (101.3 / O9)^0.5) -> 0.68156418 | Q9: =G9 * P9 -> 31.351953 | R9: =EXP(1.63 + (9.7/(H9+0.01)) - ((15.7/(H9+0.01))^2)) -> 5.4048913 | S9: =Q9 + R9 -> 36.756844 | T9: =0.784 - 0.0768 * SQRT(S9) -> 0.31838139 | U9: =MIN(1.7, (101.3 / O9)^T9) -> 0.78339952 | V9: =(G9 * U9) + R9 -> 41.441269 | W9: =EXP((-1.012 - 1.126*SIN((D9/11.73)+5.133)) + (0.106 + 0.118*SIN((D9/11.28)+5.142))*I9) -> 0.82611022 | X9: =0.65 * J9 * (N9 / O9) * W9 -> 0.24377582 | Y9: =MIN(2.2, 1.09 + (V9 / 31.5)^2) -> 2.2 | Z9: =1 + (Y9 - 1) * (8.64 * EXP(-I9/4) - 1.325) -> 1.2116882 | AA9: =MIN(1.1, 1 - MIN(0.3, 1 / (18.9 - 2.55 * SQRT(V9))) * LN(O9 / 101.3)) -> 0.76998109 | AB9: =EXP((V9/14.1) + (V9/126)^2 - (V9/23.6)^3 + (V9/25.4)^4 - 2.8) -> 6.8117545 | AC9: =IF(X9=0, "N/A", (AB9 * Z9 * AA9) / X9) -> 26.069897 | AD9: =IF(AC9>1, "NOT LIQUEFIABLE", "LIQUEFIABLE") -> NOT LIQUEFIABLE | AE9: =IF(AC9<1, 1-AC9, 0) -> 0 | AF9: =IF(D9<=20, 10 - (0.5 * D9), 0) -> 4 | AG9: =AE9 * AF9 * E9 -> 0 | AH9: =IF(AG9<=0,"Very Low",IF(AND(AG9>0,AG9<=5),"Low",IF(AND(AG9>5,AG9<=15),"High","Very High"))) -> Very Low
B10: 15.279407 | C10: 120.5691 | D10: =D9+1.5 -> 13.5 | E10: 1.5 | F10: 21 | G10: 51 | H10: 30.4 | I10: 7 | J10: 0.4 | K10: 9 | L10: SM | M10: =IF(D10<=K10, 0, (D10-K10)*9.81) -> 44.145 | N10: =IF(ROW()=2, D10*F10, N9 + (D10-D9)*F10) -> 279 | O10: =N10 - M10 -> 234.855 | P10: =MIN(1.7, (101.3 / O10)^0.5) -> 0.65675716 | Q10: =G10 * P10 -> 33.494615 | R10: =EXP(1.63 + (9.7/(H10+0.01)) - ((15.7/(H10+0.01))^2)) -> 5.3786183 | S10: =Q10 + R10 -> 38.873234 | T10: =0.784 - 0.0768 * SQRT(S10) -> 0.30516426 | U10: =MIN(1.7, (101.3 / O10)^T10) -> 0.77367213 | V10: =(G10 * U10) + R10 -> 44.835897 | W10: =EXP((-1.012 - 1.126*SIN((D10/11.73)+5.133)) + (0.106 + 0.118*SIN((D10/11.28)+5.142))*I10) -> 0.79861349 | X10: =0.65 * J10 * (N10 / O10) * W10 -> 0.24666889 | Y10: =MIN(2.2, 1.09 + (V10 / 31.5)^2) -> 2.2 | Z10: =1 + (Y10 - 1) * (8.64 * EXP(-I10/4) - 1.325) -> 1.2116882 | AA10: =MIN(1.1, 1 - MIN(0.3, 1 / (18.9 - 2.55 * SQRT(V10))) * LN(O10 / 101.3)) -> 0.74773543 | AB10: =EXP((V10/14.1) + (V10/126)^2 - (V10/23.6)^3 + (V10/25.4)^4 - 2.8) -> 28.738095 | AC10: =IF(X10=0, "N/A", (AB10 * Z10 * AA10) / X10) -> 105.55588 | AD10: =IF(AC10>1, "NOT LIQUEFIABLE", "LIQUEFIABLE") -> NOT LIQUEFIABLE | AE10: =IF(AC10<1, 1-AC10, 0) -> 0 | AF10: =IF(D10<=20, 10 - (0.5 * D10), 0) -> 3.25 | AG10: =AE10 * AF10 * E10 -> 0 | AH10: =IF(AG10<=0,"Very Low",IF(AND(AG10>0,AG10<=5),"Low",IF(AND(AG10>5,AG10<=15),"High","Very High"))) -> Very Low
B11: 15.279407 | C11: 120.5691 | D11: =D10+1.5 -> 15 | E11: 1.5 | F11: 21 | G11: 57 | H11: 25.72 | I11: 7 | J11: 0.4 | K11: 9 | L11: SM | M11: =IF(D11<=K11, 0, (D11-K11)*9.81) -> 58.86 | N11: =IF(ROW()=2, D11*F11, N10 + (D11-D10)*F11) -> 310.5 | O11: =N11 - M11 -> 251.64 | P11: =MIN(1.7, (101.3 / O11)^0.5) -> 0.63447554 | Q11: =G11 * P11 -> 36.165106 | R11: =EXP(1.63 + (9.7/(H11+0.01)) - ((15.7/(H11+0.01))^2)) -> 5.1277602 | S11: =Q11 + R11 -> 41.292866 | T11: =0.784 - 0.0768 * SQRT(S11) -> 0.29048685 | U11: =MIN(1.7, (101.3 / O11)^T11) -> 0.76772953 | V11: =(G11 * U11) + R11 -> 48.888343 | W11: =EXP((-1.012 - 1.126*SIN((D11/11.73)+5.133)) + (0.106 + 0.118*SIN((D11/11.28)+5.142))*I11) -> 0.7714163 | X11: =0.65 * J11 * (N11 / O11) * W11 -> 0.24748227 | Y11: =MIN(2.2, 1.09 + (V11 / 31.5)^2) -> 2.2 | Z11: =1 + (Y11 - 1) * (8.64 * EXP(-I11/4) - 1.325) -> 1.2116882 | AA11: =MIN(1.1, 1 - MIN(0.3, 1 / (18.9 - 2.55 * SQRT(V11))) * LN(O11 / 101.3)) -> 0.72702607 | AB11: =EXP((V11/14.1) + (V11/126)^2 - (V11/23.6)^3 + (V11/25.4)^4 - 2.8) -> 284.98351 | AC11: =IF(X11=0, "N/A", (AB11 * Z11 * AA11) / X11) -> 1014.417 | AD11: =IF(AC11>1, "NOT LIQUEFIABLE", "LIQUEFIABLE") -> NOT LIQUEFIABLE | AE11: =IF(AC11<1, 1-AC11, 0) -> 0 | AF11: =IF(D11<=20, 10 - (0.5 * D11), 0) -> 2.5 | AG11: =AE11 * AF11 * E11 -> 0 | AH11: =IF(AG11<=0,"Very Low",IF(AND(AG11>0,AG11<=5),"Low",IF(AND(AG11>5,AG11<=15),"High","Very High"))) -> Very Low
AF12: TOTAL | AG12: =SUM(AG2:AG11) -> 0 | AH12: =IF(AG12<=0,"Very Low",IF(AND(AG12>0,AG12<=5),"Low",IF(AND(AG12>5,AG12<=15),"High","Very High"))) -> Very Low
A13: No. of Boreholes | B13: Latitude | C13: Longitude | E13: Layer Thickness (z2) | F13: Total Unit Weight (y) | G13: N60 | H13: Fines Content (FC) | I13: Magnitude | J13: Peak Ground Acceleration (PGA) | K13: Gound Water Level (GWL) | L13: Soil Type | M13: Pore Pressure (u) | O13: Effective Stress | P13: Cn | Q13: N161 | R13: N160_3 | S13: N160cs | T13: m | U13: Cn_final | V13: N160cs_final | W13: rd | X13: CSR | Y13: MSFmax | Z13: MSF | AA13: Ko | AB13: CRR7.6 | AC13: FS | AD13: Remarks | AE13: Severity (Fi) | AF13: Weighting Factor | AG13: LPI | AH13: Remarks | AI13: Footing Width, B | AJ13: Depth of Footing, Df | AK13: Tolerable Settlement | AL13: Depth Factor, Fd | AM13: N | AN13: N_Design | AO13: Nc | AP13: SBC (qa) | AQ13: SBC (qa) NEW
A14: 2 | B14: 15.322512 | C14: 120.59619 | D14: 1.5 | E14: 1.5 | F14: 21 | G14: 17 | H14: 26.22 | I14: 7 | J14: 0.35 | K14: 3 | L14: ML | M14: =IF(D14<=K14, 0, (D14-K14)*9.81) -> 0 | N14: =IF(ROW()=2, D14*F14, N13 + (D14-D13)*F14) -> 31.5 | O14: =N14 - M14 -> 31.5 | P14: =MIN(1.7, (101.3 / O14)^0.5) -> 1.7 | Q14: =G14 * P14 -> 28.9 | R14: =EXP(1.63 + (9.7/(H14+0.01)) - ((15.7/(H14+0.01))^2)) -> 5.1631246 | S14: =Q14 + R14 -> 34.063125 | T14: =0.784 - 0.0768 * SQRT(S14) -> 0.33576738 | U14: =MIN(1.7, (101.3 / O14)^T14) -> 1.4802478 | V14: =(G14 * U14) + R14 -> 30.327337 | W14: =EXP((-1.012 - 1.126*SIN((D14/11.73)+5.133)) + (0.106 + 0.118*SIN((D14/11.28)+5.142))*I14) -> 0.99216797 | X14: =0.65 * J14 * (N14 / O14) * W14 -> 0.22571821 | Y14: =MIN(2.2, 1.09 + (V14 / 31.5)^2) -> 2.0169311 | Z14: =1 + (Y14 - 1) * (8.64 * EXP(-I14/4) - 1.325) -> 1.1793936 | AA14: =MIN(1.1, 1 - MIN(0.3, 1 / (18.9 - 2.55 * SQRT(V14))) * LN(O14 / 101.3)) -> 1.1 | AB14: =EXP((V14/14.1) + (V14/126)^2 - (V14/23.6)^3 + (V14/25.4)^4 - 2.8) -> 0.5061465 | AC14: =IF(X14=0, "N/A", (AB14 * Z14 * AA14) / X14) -> 2.9091163 | AD14: =IF(AC14>1, "NOT LIQUEFIABLE", "LIQUEFIABLE") -> NOT LIQUEFIABLE | AE14: =IF(AC14<1, 1-AC14, 0) -> 0 | AF14: =IF(D14<=20, 10 - (0.5 * D14), 0) -> 9.25 | AG14: =AE14 * AF14 * E14 -> 0 | AH14: =IF(AG14<=0,"Very Low",IF(AND(AG14>0,AG14<=5),"Low",IF(AND(AG14>5,AG14<=15),"High","Very High"))) -> Very Low | AI14: 3 | AJ14: 1.5 | AK14: 25 | AL14: =MIN(1 + 0.33 * (AJ14 / AI14), 1.33) -> 1.165 | AM14: =AVERAGEIFS(G14:G23, D14:D23, ">" & AJ14, D14:D23, "<" & (AJ14 + AI14 + 1.5)) -> 18.5 | AN14: {=_xlfn.LET( _xlpm.Df, AJ14, _xlpm.B, AI14, _xlpm.LayerBottoms, D14:D23, _xlpm.LayerTops, D14:D23 - E14:E23, _xlpm.N_values, G14:G23, _xlpm.FilteredN, _xlfn._xlws.FILTER(_xlpm.N_values, (_xlpm.LayerBottoms > _xlpm.Df) * (_xlpm.LayerTops < (_xlpm.Df + 2*_xlpm.B))), _xlpm.i, _xlfn.SEQUENCE(ROWS(_xlpm.FilteredN)), SUM(_xlpm.FilteredN / _xlpm.i^2) / SUM(1 / _xlpm.i^2) )} -> 18.6 | AO14: =MIN(6 * (1 + 0.2 * (AJ14 / AI14)), 9) -> 6.6 | AP14: =IF(AI14<=1.2,12*AM14*AL14*(AK14/25.4),8*AM14*((3.28*AI14+1)/(3.28*AI14))^2*AL14*(AK14/25.4)) -> 205.95024 | AQ14: {=_xlfn.LET( _xlpm.Df, AJ14, _xlpm.B, AI14, _xlpm.Settlement, AK14, _xlpm.NMeyerhof, AM14, _xlpm.NDesign, AN14, _xlpm.Nc, AO14, _xlpm.Fd, AL14, _xlpm.LayerBottoms, D14:D23, _xlpm.LayerThickness, E14:E23, _xlpm.USCS, L14:L23, _xlpm.LayerTops, _xlpm.LayerBottoms - _xlpm.LayerThickness, _xlpm.Overlap, (_xlpm.LayerBottoms > _xlpm.Df) * (_xlpm.LayerTops < (_xlpm.Df + 2*_xlpm.B)), _xlpm.FilteredUSCS, _xlfn._xlws.FILTER(_xlpm.USCS, _xlpm.Overlap, "None"), _xlpm.TotalLayers, ROWS(_xlpm.FilteredUSCS), _xlpm.CohesiveCount, SUM(--(ISNUMBER(MATCH(_xlpm.FilteredUSCS, {"CH","MH","CL","ML","OH","OL"}, 0)))), _xlpm.CohesionlessCount, SUM(--(ISNUMBER(MATCH(_xlpm.FilteredUSCS, {"GW","GP","GM","GC","SW","SP","SM","SC"}, 0)))), _xlpm.ZoneType, IF(INDEX(_xlpm.FilteredUSCS,1)="None", "No Soil", IF(_xlpm.CohesiveCount = _xlpm.TotalLayers, "Cohesive", IF(_xlpm.CohesionlessCount = _xlpm.TotalLayers, "Cohesionless", "Mixed"))), IF(_xlpm.ZoneType = "Cohesive", 2 * _xlpm.NDesign * _xlpm.Nc, IF(_xlpm.ZoneType = "Cohesionless", IF(_xlpm.B <= 1.2, 12 * _xlpm.NMeyerhof * _xlpm.Fd * (_xlpm.Settlement / 25.4), 8 * _xlpm.NMeyerhof * ((3.28 * _xlpm.B + 1) / (3.28 * _xlpm.B))^2 * _xlpm.Fd * (_xlpm.Settlement / 25.4) ), "Mixed Zone - Needs Manual Analysis" ) ) )} -> Mixed Zone - Needs Manual Analysis | AR14: {=_xlfn.LET( _xlpm.Df, AJ14, _xlpm.B, AI14, _xlpm.Settlement, AK14, _xlpm.NMeyerhof, AM14, _xlpm.NDesign, AN14, _xlpm.Nc, AO14, _xlpm.Fd, AL14, _xlpm.LayerBottoms, D14:D23, _xlpm.LayerThickness, E14:E23, _xlpm.USCS, L14:L23, _xlpm.LayerTops, _xlpm.LayerBottoms - _xlpm.LayerThickness, _xlpm.Overlap, (_xlpm.LayerBottoms > _xlpm.Df) * (_xlpm.LayerTops < (_xlpm.Df + 2*_xlpm.B)), _xlpm.FilteredUSCS, _xlfn._xlws.FILTER(_xlpm.USCS, _xlpm.Overlap, "None"), _xlpm.TotalLayers, ROWS(_xlpm.FilteredUSCS), _xlpm.CohesiveCount, SUM(--(ISNUMBER(MATCH(_xlpm.FilteredUSCS, {"CH","MH","CL","ML","OH","OL"}, 0)))), _xlpm.CohesionlessCount, SUM(--(ISNUMBER(MATCH(_xlpm.FilteredUSCS, {"GW","GP","GM","GC","SW","SP","SM","SC"}, 0)))), _xlpm.ZoneType, IF(INDEX(_xlpm.FilteredUSCS,1)="None", "No Soil", IF(_xlpm.CohesiveCount = _xlpm.TotalLayers, "Cohesive", IF(_xlpm.CohesionlessCount = _xlpm.TotalLayers, "Cohesionless", "Mixed"))), _xlpm.Qa_Cohesive, 2 * _xlpm.NDesign * _xlpm.Nc, _xlpm.Qa_Cohesionless, IF(_xlpm.B <= 1.2, 12 * _xlpm.NMeyerhof * _xlpm.Fd * (_xlpm.Settlement / 25.4), 8 * _xlpm.NMeyerhof * ((3.28 * _xlpm.B + 1) / (3.28 * _xlpm.B))^2 * _xlpm.Fd * (_xlpm.Settlement / 25.4)), IF(_xlpm.ZoneType = "Cohesive", _xlpm.Qa_Cohesive, IF(_xlpm.ZoneType = "Cohesionless", _xlpm.Qa_Cohesionless, IF(_xlpm.ZoneType = "Mixed", MIN(_xlpm.Qa_Cohesive, _xlpm.Qa_Cohesionless), "Invalid Data" ) ) ) )} -> 205.95024 | AS14: {=_xlfn.LET( _xlpm.Df, AJ14, _xlpm.B, AI14, _xlpm.Settlement, AK14, _xlpm.NMeyerhof, AM14, _xlpm.NDesign, AN14, _xlpm.Nc, AO14, _xlpm.Fd, AL14, _xlpm.LayerBottoms, D14:D23, _xlpm.LayerThickness, E14:E23, _xlpm.Material, L14:L23, _xlpm.LayerTops, _xlpm.LayerBottoms - _xlpm.LayerThickness, _xlpm.Overlap, (_xlpm.LayerBottoms > _xlpm.Df) * (_xlpm.LayerTops < (_xlpm.Df + 2*_xlpm.B)), _xlpm.FilteredMat, _xlfn._xlws.FILTER(_xlpm.Material, _xlpm.Overlap, "None"), _xlpm.TotalLayers, ROWS(_xlpm.FilteredMat), _xlpm.RockCount, SUM(--(ISNUMBER(MATCH(_xlpm.FilteredMat, {"Sandstone","Basalt","Cobblestone","Cobble Stone","Coring","Tuff"}, 0)))), _xlpm.CohesiveCount, SUM(--(ISNUMBER(MATCH(_xlpm.FilteredMat, {"CH","MH","CL","ML","OH","OL","Silty Tuff"}, 0)))), _xlpm.CohesionlessCount, SUM(--(ISNUMBER(MATCH(_xlpm.FilteredMat, {"GW","GP","GM","GC","SW","SP","SM","SC","Gravel"}, 0)))), _xlpm.ZoneType, IF(INDEX(_xlpm.FilteredMat,1)="None", "No Soil", IF(_xlpm.RockCount > 0, "Rock", IF(_xlpm.CohesiveCount = _xlpm.TotalLayers, "Cohesive", IF(_xlpm.CohesionlessCount = _xlpm.TotalLayers, "Cohesionless", "Mixed" ) ) ) ), _xlpm.Qa_Cohesive, 2 * _xlpm.NDesign * _xlpm.Nc, _xlpm.Qa_Cohesionless, IF(_xlpm.B <= 1.2, 12 * _xlpm.NMeyerhof * _xlpm.Fd * (_xlpm.Settlement / 25.4), 8 * _xlpm.NMeyerhof * ((3.28 * _xlpm.B + 1) / (3.28 * _xlpm.B))^2 * _xlpm.Fd * (_xlpm.Settlement / 25.4)), IF(_xlpm.ZoneType = "Rock", "N/A - Rock/Cobble Detected (Use Rock Mechanics)", IF(_xlpm.ZoneType = "Cohesive", _xlpm.Qa_Cohesive, IF(_xlpm.ZoneType = "Cohesionless", _xlpm.Qa_Cohesionless, IF(_xlpm.ZoneType = "Mixed", MIN(_xlpm.Qa_Cohesive, _xlpm.Qa_Cohesionless), "Invalid Data" ) ) ) ) )} -> 205.95024
B15: 15.322512 | C15: 120.59619 | D15: =D14+1.5 -> 3 | E15: 1.5 | F15: 21 | G15: 17 | H15: 26.22 | I15: 7 | J15: 0.35 | K15: 3 | L15: ML | M15: =IF(D15<=K15, 0, (D15-K15)*9.81) -> 0 | N15: =IF(ROW()=2, D15*F15, N14 + (D15-D14)*F15) -> 63 | O15: =N15 - M15 -> 63 | P15: =MIN(1.7, (101.3 / O15)^0.5) -> 1.2680444 | Q15: =G15 * P15 -> 21.556754 | R15: =EXP(1.63 + (9.7/(H15+0.01)) - ((15.7/(H15+0.01))^2)) -> 5.1631246 | S15: =Q15 + R15 -> 26.719879 | T15: =0.784 - 0.0768 * SQRT(S15) -> 0.38701101 | U15: =MIN(1.7, (101.3 / O15)^T15) -> 1.2017893 | V15: =(G15 * U15) + R15 -> 25.593543 | W15: =EXP((-1.012 - 1.126*SIN((D15/11.73)+5.133)) + (0.106 + 0.118*SIN((D15/11.28)+5.142))*I15) -> 0.97433785 | X15: =0.65 * J15 * (N15 / O15) * W15 -> 0.22166186 | Y15: =MIN(2.2, 1.09 + (V15 / 31.5)^2) -> 1.7501456 | Z15: =1 + (Y15 - 1) * (8.64 * EXP(-I15/4) - 1.325) -> 1.1323308 | AA15: =MIN(1.1, 1 - MIN(0.3, 1 / (18.9 - 2.55 * SQRT(V15))) * LN(O15 / 101.3)) -> 1.0791648 | AB15: =EXP((V15/14.1) + (V15/126)^2 - (V15/23.6)^3 + (V15/25.4)^4 - 2.8) -> 0.30477162 | AC15: =IF(X15=0, "N/A", (AB15 * Z15 * AA15) / X15) -> 1.6801368 | AD15: =IF(AC15>1, "NOT LIQUEFIABLE", "LIQUEFIABLE") -> NOT LIQUEFIABLE | AE15: =IF(AC15<1, 1-AC15, 0) -> 0 | AF15: =IF(D15<=20, 10 - (0.5 * D15), 0) -> 8.5 | AG15: =AE15 * AF15 * E15 -> 0 | AH15: =IF(AG15<=0,"Very Low",IF(AND(AG15>0,AG15<=5),"Low",IF(AND(AG15>5,AG15<=15),"High","Very High"))) -> Very Low
B16: 15.322512 | C16: 120.59619 | D16: =D15+1.5 -> 4.5 | E16: 1.5 | F16: 21 | G16: 20 | H16: 24.22 | I16: 7 | J16: 0.35 | K16: 3 | L16: ML | M16: =IF(D16<=K16, 0, (D16-K16)*9.81) -> 14.715 | N16: =IF(ROW()=2, D16*F16, N15 + (D16-D15)*F16) -> 94.5 | O16: =N16 - M16 -> 79.785 | P16: =MIN(1.7, (101.3 / O16)^0.5) -> 1.1267929 | Q16: =G16 * P16 -> 22.535858 | R16: =EXP(1.63 + (9.7/(H16+0.01)) - ((15.7/(H16+0.01))^2)) -> 5.0052221 | S16: =Q16 + R16 -> 27.54108 | T16: =0.784 - 0.0768 * SQRT(S16) -> 0.3809567 | U16: =MIN(1.7, (101.3 / O16)^T16) -> 1.0952184 | V16: =(G16 * U16) + R16 -> 26.909589 | W16: =EXP((-1.012 - 1.126*SIN((D16/11.73)+5.133)) + (0.106 + 0.118*SIN((D16/11.28)+5.142))*I16) -> 0.95382539 | X16: =0.65 * J16 * (N16 / O16) * W16 -> 0.2570164 | Y16: =MIN(2.2, 1.09 + (V16 / 31.5)^2) -> 1.8197818 | Z16: =1 + (Y16 - 1) * (8.64 * EXP(-I16/4) - 1.325) -> 1.1446151 | AA16: =MIN(1.1, 1 - MIN(0.3, 1 / (18.9 - 2.55 * SQRT(V16))) * LN(O16 / 101.3)) -> 1.0420928 | AB16: =EXP((V16/14.1) + (V16/126)^2 - (V16/23.6)^3 + (V16/25.4)^4 - 2.8) -> 0.34348959 | AC16: =IF(X16=0, "N/A", (AB16 * Z16 * AA16) / X16) -> 1.5941112 | AD16: =IF(AC16>1, "NOT LIQUEFIABLE", "LIQUEFIABLE") -> NOT LIQUEFIABLE | AE16: =IF(AC16<1, 1-AC16, 0) -> 0 | AF16: =IF(D16<=20, 10 - (0.5 * D16), 0) -> 7.75 | AG16: =AE16 * AF16 * E16 -> 0 | AH16: =IF(AG16<=0,"Very Low",IF(AND(AG16>0,AG16<=5),"Low",IF(AND(AG16>5,AG16<=15),"High","Very High"))) -> Very Low
B17: 15.322512 | C17: 120.59619 | D17: =D16+1.5 -> 6 | E17: 1.5 | F17: 20 | G17: 24 | H17: 21.86 | I17: 7 | J17: 0.35 | K17: 3 | L17: SM | M17: =IF(D17<=K17, 0, (D17-K17)*9.81) -> 29.43 | N17: =IF(ROW()=2, D17*F17, N16 + (D17-D16)*F17) -> 124.5 | O17: =N17 - M17 -> 95.07 | P17: =MIN(1.7, (101.3 / O17)^0.5) -> 1.0322454 | Q17: =G17 * P17 -> 24.773891 | R17: =EXP(1.63 + (9.7/(H17+0.01)) - ((15.7/(H17+0.01))^2)) -> 4.7501709 | S17: =Q17 + R17 -> 29.524062 | T17: =0.784 - 0.0768 * SQRT(S17) -> 0.36669915 | U17: =MIN(1.7, (101.3 / O17)^T17) -> 1.0235485 | V17: =(G17 * U17) + R17 -> 29.315334 | W17: =EXP((-1.012 - 1.126*SIN((D17/11.73)+5.133)) + (0.106 + 0.118*SIN((D17/11.28)+5.142))*I17) -> 0.93104429 | X17: =0.65 * J17 * (N17 / O17) * W17 -> 0.27738157 | Y17: =MIN(2.2, 1.09 + (V17 / 31.5)^2) -> 1.9561011 | Z17: =1 + (Y17 - 1) * (8.64 * EXP(-I17/4) - 1.325) -> 1.1686628 | AA17: =MIN(1.1, 1 - MIN(0.3, 1 / (18.9 - 2.55 * SQRT(V17))) * LN(O17 / 101.3)) -> 1.0124619 | AB17: =EXP((V17/14.1) + (V17/126)^2 - (V17/23.6)^3 + (V17/25.4)^4 - 2.8) -> 0.4452716 | AC17: =IF(X17=0, "N/A", (AB17 * Z17 * AA17) / X17) -> 1.899395 | AD17: =IF(AC17>1, "NOT LIQUEFIABLE", "LIQUEFIABLE") -> NOT LIQUEFIABLE | AE17: =IF(AC17<1, 1-AC17, 0) -> 0 | AF17: =IF(D17<=20, 10 - (0.5 * D17), 0) -> 7 | AG17: =AE17 * AF17 * E17 -> 0 | AH17: =IF(AG17<=0,"Very Low",IF(AND(AG17>0,AG17<=5),"Low",IF(AND(AG17>5,AG17<=15),"High","Very High"))) -> Very Low
B18: 15.322512 | C18: 120.59619 | D18: =D17+1.5 -> 7.5 | E18: 1.5 | F18: 20 | G18: 29 | H18: 23.89 | I18: 7 | J18: 0.35 | K18: 3 | L18: SM | M18: =IF(D18<=K18, 0, (D18-K18)*9.81) -> 44.145 | N18: =IF(ROW()=2, D18*F18, N17 + (D18-D17)*F18) -> 154.5 | O18: =N18 - M18 -> 110.355 | P18: =MIN(1.7, (101.3 / O18)^0.5) -> 0.95809531 | Q18: =G18 * P18 -> 27.784764 | R18: =EXP(1.63 + (9.7/(H18+0.01)) - ((15.7/(H18+0.01))^2)) -> 4.9745513 | S18: =Q18 + R18 -> 32.759315 | T18: =0.784 - 0.0768 * SQRT(S18) -> 0.34442941 | U18: =MIN(1.7, (101.3 / O18)^T18) -> 0.97094187 | V18: =(G18 * U18) + R18 -> 33.131866 | W18: =EXP((-1.012 - 1.126*SIN((D18/11.73)+5.133)) + (0.106 + 0.118*SIN((D18/11.28)+5.142))*I18) -> 0.90643373 | X18: =0.65 * J18 * (N18 / O18) * W18 -> 0.28870475 | Y18: =MIN(2.2, 1.09 + (V18 / 31.5)^2) -> 2.1962943 | Z18: =1 + (Y18 - 1) * (8.64 * EXP(-I18/4) - 1.325) -> 1.2110345 | AA18: =MIN(1.1, 1 - MIN(0.3, 1 / (18.9 - 2.55 * SQRT(V18))) * LN(O18 / 101.3)) -> 0.97972206 | AB18: =EXP((V18/14.1) + (V18/126)^2 - (V18/23.6)^3 + (V18/25.4)^4 - 2.8) -> 0.77644436 | AC18: =IF(X18=0, "N/A", (AB18 * Z18 * AA18) / X18) -> 3.1909193 | AD18: =IF(AC18>1, "NOT LIQUEFIABLE", "LIQUEFIABLE") -> NOT LIQUEFIABLE | AE18: =IF(AC18<1, 1-AC18, 0) -> 0 | AF18: =IF(D18<=20, 10 - (0.5 * D18), 0) -> 6.25 | AG18: =AE18 * AF18 * E18 -> 0 | AH18: =IF(AG18<=0,"Very Low",IF(AND(AG18>0,AG18<=5),"Low",IF(AND(AG18>5,AG18<=15),"High","Very High"))) -> Very Low
B19: 15.322512 | C19: 120.59619 | D19: =D18+1.5 -> 9 | E19: 1.5 | F19: 21 | G19: 46 | H19: 23.2 | I19: 7 | J19: 0.35 | K19: 3 | L19: SM | M19: =IF(D19<=K19, 0, (D19-K19)*9.81) -> 58.86 | N19: =IF(ROW()=2, D19*F19, N18 + (D19-D18)*F19) -> 186 | O19: =N19 - M19 -> 127.14 | P19: =MIN(1.7, (101.3 / O19)^0.5) -> 0.89261385 | Q19: =G19 * P19 -> 41.060237 | R19: =EXP(1.63 + (9.7/(H19+0.01)) - ((15.7/(H19+0.01))^2)) -> 4.9055258 | S19: =Q19 + R19 -> 45.965763 | T19: =0.784 - 0.0768 * SQRT(S19) -> 0.26331094 | U19: =MIN(1.7, (101.3 / O19)^T19) -> 0.94192947 | V19: =(G19 * U19) + R19 -> 48.234281 | W19: =EXP((-1.012 - 1.126*SIN((D19/11.73)+5.133)) + (0.106 + 0.118*SIN((D19/11.28)+5.142))*I19) -> 0.88044424 | X19: =0.65 * J19 * (N19 / O19) * W19 -> 0.29303129 | Y19: =MIN(2.2, 1.09 + (V19 / 31.5)^2) -> 2.2 | Z19: =1 + (Y19 - 1) * (8.64 * EXP(-I19/4) - 1.325) -> 1.2116882 | AA19: =MIN(1.1, 1 - MIN(0.3, 1 / (18.9 - 2.55 * SQRT(V19))) * LN(O19 / 101.3)) -> 0.93183927 | AB19: =EXP((V19/14.1) + (V19/126)^2 - (V19/23.6)^3 + (V19/25.4)^4 - 2.8) -> 187.5872 | AC19: =IF(X19=0, "N/A", (AB19 * Z19 * AA19) / X19) -> 722.80493 | AD19: =IF(AC19>1, "NOT LIQUEFIABLE", "LIQUEFIABLE") -> NOT LIQUEFIABLE | AE19: =IF(AC19<1, 1-AC19, 0) -> 0 | AF19: =IF(D19<=20, 10 - (0.5 * D19), 0) -> 5.5 | AG19: =AE19 * AF19 * E19 -> 0 | AH19: =IF(AG19<=0,"Very Low",IF(AND(AG19>0,AG19<=5),"Low",IF(AND(AG19>5,AG19<=15),"High","Very High"))) -> Very Low
B20: 15.322512 | C20: 120.59619 | D20: =D19+1.5 -> 10.5 | E20: 1.5 | F20: 21 | G20: 49 | H20: 21.2 | I20: 7 | J20: 0.35 | K20: 3 | L20: SM | M20: =IF(D20<=K20, 0, (D20-K20)*9.81) -> 73.575 | N20: =IF(ROW()=2, D20*F20, N19 + (D20-D19)*F20) -> 217.5 | O20: =N20 - M20 -> 143.925 | P20: =MIN(1.7, (101.3 / O20)^0.5) -> 0.83895101 | Q20: =G20 * P20 -> 41.1086 | R20: =EXP(1.63 + (9.7/(H20+0.01)) - ((15.7/(H20+0.01))^2)) -> 4.6618409 | S20: =Q20 + R20 -> 45.770441 | T20: =0.784 - 0.0768 * SQRT(S20) -> 0.2644184 | U20: =MIN(1.7, (101.3 / O20)^T20) -> 0.91131624 | V20: =(G20 * U20) + R20 -> 49.316337 | W20: =EXP((-1.012 - 1.126*SIN((D20/11.73)+5.133)) + (0.106 + 0.118*SIN((D20/11.28)+5.142))*I20) -> 0.8535246 | X20: =0.65 * J20 * (N20 / O20) * W20 -> 0.29344078 | Y20: =MIN(2.2, 1.09 + (V20 / 31.5)^2) -> 2.2 | Z20: =1 + (Y20 - 1) * (8.64 * EXP(-I20/4) - 1.325) -> 1.2116882 | AA20: =MIN(1.1, 1 - MIN(0.3, 1 / (18.9 - 2.55 * SQRT(V20))) * LN(O20 / 101.3)) -> 0.89463822 | AB20: =EXP((V20/14.1) + (V20/126)^2 - (V20/23.6)^3 + (V20/25.4)^4 - 2.8) -> 378.74142 | AC20: =IF(X20=0, "N/A", (AB20 * Z20 * AA20) / X20) -> 1399.1384 | AD20: =IF(AC20>1, "NOT LIQUEFIABLE", "LIQUEFIABLE") -> NOT LIQUEFIABLE | AE20: =IF(AC20<1, 1-AC20, 0) -> 0 | AF20: =IF(D20<=20, 10 - (0.5 * D20), 0) -> 4.75 | AG20: =AE20 * AF20 * E20 -> 0 | AH20: =IF(AG20<=0,"Very Low",IF(AND(AG20>0,AG20<=5),"Low",IF(AND(AG20>5,AG20<=15),"High","Very High"))) -> Very Low
B21: 15.322512 | C21: 120.59619 | D21: =D20+1.5 -> 12 | E21: 1.5 | F21: 21 | G21: 63 | H21: 21.43 | I21: 7 | J21: 0.35 | K21: 3 | L21: SM | M21: =IF(D21<=K21, 0, (D21-K21)*9.81) -> 88.29 | N21: =IF(ROW()=2, D21*F21, N20 + (D21-D20)*F21) -> 249 | O21: =N21 - M21 -> 160.71 | P21: =MIN(1.7, (101.3 / O21)^0.5) -> 0.79393194 | Q21: =G21 * P21 -> 50.017712 | R21: =EXP(1.63 + (9.7/(H21+0.01)) - ((15.7/(H21+0.01))^2)) -> 4.6935868 | S21: =Q21 + R21 -> 54.711299 | T21: =0.784 - 0.0768 * SQRT(S21) -> 0.21593278 | U21: =MIN(1.7, (101.3 / O21)^T21) -> 0.90514852 | V21: =(G21 * U21) + R21 -> 61.717944 | W21: =EXP((-1.012 - 1.126*SIN((D21/11.73)+5.133)) + (0.106 + 0.118*SIN((D21/11.28)+5.142))*I21) -> 0.82611022 | X21: =0.65 * J21 * (N21 / O21) * W21 -> 0.29118959 | Y21: =MIN(2.2, 1.09 + (V21 / 31.5)^2) -> 2.2 | Z21: =1 + (Y21 - 1) * (8.64 * EXP(-I21/4) - 1.325) -> 1.2116882 | AA21: =MIN(1.1, 1 - MIN(0.3, 1 / (18.9 - 2.55 * SQRT(V21))) * LN(O21 / 101.3)) -> 1.1 | AB21: =EXP((V21/14.1) + (V21/126)^2 - (V21/23.6)^3 + (V21/25.4)^4 - 2.8) -> 1.4472993e+08 | AC21: =IF(X21=0, "N/A", (AB21 * Z21 * AA21) / X21) -> 6.624698e+08 | AD21: =IF(AC21>1, "NOT LIQUEFIABLE", "LIQUEFIABLE") -> NOT LIQUEFIABLE | AE21: =IF(AC21<1, 1-AC21, 0) -> 0 | AF21: =IF(D21<=20, 10 - (0.5 * D21), 0) -> 4 | AG21: =AE21 * AF21 * E21 -> 0 | AH21: =IF(AG21<=0,"Very Low",IF(AND(AG21>0,AG21<=5),"Low",IF(AND(AG21>5,AG21<=15),"High","Very High"))) -> Very Low
B22: 15.322512 | C22: 120.59619 | D22: =D21+1.5 -> 13.5 | E22: 1.5 | F22: 21 | G22: 71 | H22: 21.98 | I22: 7 | J22: 0.35 | K22: 3 | L22: SM | M22: =IF(D22<=K22, 0, (D22-K22)*9.81) -> 103.005 | N22: =IF(ROW()=2, D22*F22, N21 + (D22-D21)*F22) -> 280.5 | O22: =N22 - M22 -> 177.495 | P22: =MIN(1.7, (101.3 / O22)^0.5) -> 0.75546032 | Q22: =G22 * P22 -> 53.637683 | R22: =EXP(1.63 + (9.7/(H22+0.01)) - ((15.7/(H22+0.01))^2)) -> 4.7653426 | S22: =Q22 + R22 -> 58.403026 | T22: =0.784 - 0.0768 * SQRT(S22) -> 0.19708002 | U22: =MIN(1.7, (101.3 / O22)^T22) -> 0.89535632 | V22: =(G22 * U22) + R22 -> 68.335641 | W22: =EXP((-1.012 - 1.126*SIN((D22/11.73)+5.133)) + (0.106 + 0.118*SIN((D22/11.28)+5.142))*I22) -> 0.79861349 | X22: =0.65 * J22 * (N22 / O22) * W22 -> 0.28712089 | Y22: =MIN(2.2, 1.09 + (V22 / 31.5)^2) -> 2.2 | Z22: =1 + (Y22 - 1) * (8.64 * EXP(-I22/4) - 1.325) -> 1.2116882 | AA22: =MIN(1.1, 1 - MIN(0.3, 1 / (18.9 - 2.55 * SQRT(V22))) * LN(O22 / 101.3)) -> 1.1 | AB22: =EXP((V22/14.1) + (V22/126)^2 - (V22/23.6)^3 + (V22/25.4)^4 - 2.8) -> 1.6822512e+13 | AC22: =IF(X22=0, "N/A", (AB22 * Z22 * AA22) / X22) -> 7.8092558e+13 | AD22: =IF(AC22>1, "NOT LIQUEFIABLE", "LIQUEFIABLE") -> NOT LIQUEFIABLE | AE22: =IF(AC22<1, 1-AC22, 0) -> 0 | AF22: =IF(D22<=20, 10 - (0.5 * D22), 0) -> 3.25 | AG22: =AE22 * AF22 * E22 -> 0 | AH22: =IF(AG22<=0,"Very Low",IF(AND(AG22>0,AG22<=5),"Low",IF(AND(AG22>5,AG22<=15),"High","Very High"))) -> Very Low
B23: 15.322512 | C23: 120.59619 | D23: =D22+1.5 -> 15 | E23: 1.5 | F23: 21 | G23: 100 | H23: 21.74 | I23: 7 | J23: 0.35 | K23: 3 | L23: SM | M23: =IF(D23<=K23, 0, (D23-K23)*9.81) -> 117.72 | N23: =IF(ROW()=2, D23*F23, N22 + (D23-D22)*F23) -> 312 | O23: =N23 - M23 -> 194.28 | P23: =MIN(1.7, (101.3 / O23)^0.5) -> 0.72208891 | Q23: =G23 * P23 -> 72.208891 | R23: =EXP(1.63 + (9.7/(H23+0.01)) - ((15.7/(H23+0.01))^2)) -> 4.7347331 | S23: =Q23 + R23 -> 76.943624 | T23: =0.784 - 0.0768 * SQRT(S23) -> 0.11032949 | U23: =MIN(1.7, (101.3 / O23)^T23) -> 0.93067225 | V23: =(G23 * U23) + R23 -> 97.801958 | W23: =EXP((-1.012 - 1.126*SIN((D23/11.73)+5.133)) + (0.106 + 0.118*SIN((D23/11.28)+5.142))*I23) -> 0.7714163 | X23: =0.65 * J23 * (N23 / O23) * W23 -> 0.28183616 | Y23: =MIN(2.2, 1.09 + (V23 / 31.5)^2) -> 2.2 | Z23: =1 + (Y23 - 1) * (8.64 * EXP(-I23/4) - 1.325) -> 1.2116882 | AA23: =MIN(1.1, 1 - MIN(0.3, 1 / (18.9 - 2.55 * SQRT(V23))) * LN(O23 / 101.3)) -> 1.1 | AB23: =EXP((V23/14.1) + (V23/126)^2 - (V23/23.6)^3 + (V23/25.4)^4 - 2.8) -> 4.0983876e+66 | AC23: =IF(X23=0, "N/A", (AB23 * Z23 * AA23) / X23) -> 1.9382058e+67 | AD23: =IF(AC23>1, "NOT LIQUEFIABLE", "LIQUEFIABLE") -> NOT LIQUEFIABLE | AE23: =IF(AC23<1, 1-AC23, 0) -> 0 | AF23: =IF(D23<=20, 10 - (0.5 * D23), 0) -> 2.5 | AG23: =AE23 * AF23 * E23 -> 0 | AH23: =IF(AG23<=0,"Very Low",IF(AND(AG23>0,AG23<=5),"Low",IF(AND(AG23>5,AG23<=15),"High","Very High"))) -> Very Low
AF24: TOTAL | AG24: =SUM(AG14:AG23) -> 0 | AH24: =IF(AG24<=0,"Very Low",IF(AND(AG24>0,AG24<=5),"Low",IF(AND(AG24>5,AG24<=15),"High","Very High"))) -> Very Low
A25: No. of Boreholes | B25: Latitude | C25: Longitude | G25: N60 | H25: Fines Content (FC) | I25: Magnitude | J25: Peak Ground Acceleration (PGA) | K25: Gound Water Level (GWL) | L25: Soil Type | M25: Pore Pressure (u) | O25: Effective Stress | P25: Cn | Q25: N162 | R25: N160_4 | S25: N160cs | T25: m | U25: Cn_final | V25: N160cs_final | W25: rd | X25: CSR | Y25: MSFmax | Z25: MSF | AA25: Ko | AB25: CRR7.7 | AC25: FS | AD25: Remarks | AE25: Severity (Fi) | AF25: Weighting Factor | AG25: LPI | AH25: Remarks | AI25: Footing Width, B | AJ25: Depth of Footing, Df | AK25: Tolerable Settlement | AL25: Depth Factor, Fd | AM25: N | AN25: N_Design | AO25: Nc | AP25: SBC (qa) | AQ25: SBC (qa) NEW
