Workbook

Sheet Summary
S1: Cyclic Strength Ratio (CSR) | AK1: The user provides this value | CB1: SOIL BEARING CAPACITY BASED ON SPT-N VALUE (KPA) - Bowles (1988) | CJ1: SETTLEMENT BASED ON SPT-N VALUE - 25mm - Bowles(1988)
Z2: Sample | AA2: Depth (z) | AB2: Thickness(h) | AC2: GWL | AD2: Unit Weight (γ) | AE2: Total Stress (𝜎) | AF2: Porepressure (𝑢) | AG2: Effective Stress (𝜎′) | AH2: Peak Ground Acceleration (a/g) | AI2: Stress Reduction Coefficient (rd) | AJ2: CSR | AK2: Magnitude (Mw) | AL2: MSF/km | AM2: Fines Content | AN2: USCS | AO2: USCS Symbol | AP2: N1(60) | AQ2: (N1)60cs | AR2: Relative Density (Dr) % | AS2: f | AT2: k𝜎 | AU2: ka | AV2: CRR(7.5) | AW2: FS | AX2: REMARK | AY2: Weighing Factor (wi) | AZ2: Severity Factor (Fi) | BA2: LPI | BB2: Remarks | BX2: Sample | BY2: USCS | BZ2: Depth | CA2: (N1)60 | CB2: Width (B) | CC2: Depth (D) | CD2: Depth Factor (Kd) | CE2: N-Value(ave) | CF2: Qu (KPa) | CG2: Qa (KPa) | CH2: FS | CJ2: Si | CK2: Q-actual load (KPa) | CL2: Qa (KPa) | CM2: Settlement (mm)
Z3: 1 | AA3: 1.5 | AB3: 1.5 | AC3: 1.5 | AD3: 21 | AE3: =AB3*AD3 -> 31.5 | AF3: =IF(AA3>AC3,(AA3-AC3)*9.81,0) -> 0 | AG3: =AE3-AF3 -> 31.5 | AH3: 0.3 | AI3: =IF(AA3<=9.15,(1-0.00765*AA3), IF(AA3<=23, (1.174-0.0267*AA3))) -> 0.988525 | AJ3: =0.65*AH3*(AE3/AG3)*AI3 -> 0.19276238 | AK3: 6.5 | AL3: =ROUND((10^2.24)/(AK3^2.56),6) -> 1.441922 | AM3: 31.11 | AN3: Silty Sand | AO3: SM | AP3: 22.5 | AQ3: =IF(AM3<=5, AP3, IF(AM3<35, EXP(1.76-(190/AM3^2))+(0.99+(AM3^1.5/1000))*AP3, 5+(1.2*AP3))) -> 30.955594 | AR3: =IF(OR(AO3="CL", AO3="CH", AO3="ML", AO3="MH", AO3="OL", AO3="OH", AO3="Pt", AO3="CL-ML"), "N/A (Cohesive)", SQRT(AP3/60)*100) -> 61.237244 | AS3: =IF(AR3="N/A (Cohesive)", "-", IF(AR3<=40, 0.8, IF(AR3<=70, 0.7, 0.6))) -> 0.7 | AT3: =IF(OR(AS3="-", AS3=""), 1, MIN(1, (AG3/100)^(AS3-1))) -> 1 | AU3: =IF(OR(AS4="N/A (Cohesive)", AS4="-"), 1, IF(AG4/100 <= 3, 1, 1)) -> 1 | AV3: =IF(AQ3>=30, 0.6, (1/(34-AQ3))+(AQ3/135)+(50/((10*AQ3)+45)^2)-(1/200)) -> 0.6 | AW3: =((AV3*AL3*AT3*AU3)/AJ3) -> 4.488185 | AX3: =IF(AW3>1, "NOT LIQUEFIABLE", "LIQUEFIABLE") -> NOT LIQUEFIABLE | AY3: =IF(AA3<20, 10-(0.5*AA3), 0) -> 9.25 | AZ3: =IF(AW3<1, 1-AW3, 0) -> 0 | BA3: =AB3*AY3*AZ3 -> 0 | BB3: =IF(BA3 > 15, "Very High", IF(BA3 > 5, "High", IF(BA3 > 0, "Low", "Very Low"))) -> Very Low | BX3: 1 | BY3: Silty Sand | BZ3: 1.5 | CA3: 22.5 | CB3: 2 | CC3: 1.5 | CD3: =MIN(1.33, 1 + 0.33 * (CC3/CB3)) -> 1.2475 | CE3: =AVERAGEIFS($CA$3:$CA$8, $BZ$3:$BZ$8, ">=" & CC3,$BZ$3:$BZ$8, "<=" & (CC3 + 2 * CB3)) -> 29.75 | CF3: =(CE3/2.5)*47.88*CD3 -> 710.79057 | CG3: =IF(CB3<=1.22, 20*CE3*CD3, 12.5*CE3*((CB3+0.305)/CB3)^2*CD3) -> 616.19675 | CH3: =CF3/CG3 -> 1.1535124 | CJ3: 25 | CK3: 50 | CL3: =CG3 -> 616.19675 | CM3: =25.4 * (CK3/CL3) -> 2.06103
Z4: 2 | AA4: 3 | AB4: 1.5 | AC4: 1.5 | AD4: 20 | AE4: =AE3+(AB4*AD4) -> 61.5 | AF4: =IF(AA4>AC4,(AA4-AC4)*9.81,0) -> 14.715 | AG4: =AE4-AF4 -> 46.785 | AH4: 0.3 | AI4: =IF(AA4<=9.15,(1-0.00765*AA4), IF(AA4<=23, (1.174-0.0267*AA4))) -> 0.97705 | AJ4: =0.65*AH4*(AE4/AG4)*AI4 -> 0.25044933 | AK4: 6.5 | AL4: =ROUND((10^2.24)/(AK4^2.56),6) -> 1.441922 | AM4: 25.77 | AN4: Silty Sand | AO4: SM | AP4: 32.25 | AQ4: =IF(AM4<=5, AP4, IF(AM4<35, EXP(1.76-(190/AM4^2))+(0.99+(AM4^1.5/1000))*AP4, 5+(1.2*AP4))) -> 40.512631 | AR4: =IF(OR(AO4="CL", AO4="CH", AO4="ML", AO4="MH", AO4="OL", AO4="OH", AO4="Pt", AO4="CL-ML"), "N/A (Cohesive)", SQRT(AP4/60)*100) -> 73.314391 | AS4: =IF(AR4<=40, 0.8, IF(AR4<=70, 0.7, 0.6)) -> 0.6 | AT4: =IF(OR(AS4="-", AS4=""), 1, MIN(1, (AG4/100)^(AS4-1))) -> 1 | AU4: =IF(OR(AS5="N/A (Cohesive)", AS5="-"), 1, IF(AG5/100 <= 3, 1, 1)) -> 1 | AV4: =IF(AQ4>=30, 0.6, (1/(34-AQ4))+(AQ4/135)+(50/((10*AQ4)+45)^2)-(1/200)) -> 0.6 | AW4: =((AV4*AL4*AT4*AU4)/AJ4) -> 3.4544041 | AX4: =IF(AW4>1, "NOT LIQUEFIABLE", "LIQUEFIABLE") -> NOT LIQUEFIABLE | AY4: =IF(AA4<20, 10-(0.5*AA4), 0) -> 8.5 | AZ4: =IF(AW4<1, 1-AW4, 0) -> 0 | BA4: =AB4*AY4*AZ4 -> 0 | BB4: =IF(BA4 > 15, "Very High", IF(BA4 > 5, "High", IF(BA4 > 0, "Low", "Very Low"))) -> Very Low | BX4: 2 | BY4: Silty Sand | BZ4: 3 | CA4: 32.25 | CB4: 2.5 | CC4: 1.5 | CD4: =MIN(1.33, 1 + 0.33 * (CC4/CB4)) -> 1.198 | CE4: =AVERAGEIFS($CA$3:$CA$8, $BZ$3:$BZ$8, ">=" & CC4,$BZ$3:$BZ$8, "<=" & (CC4 + 2 * CB4)) -> 30.1875 | CF4: =(CE4/2.5)*47.88*CD4 -> 692.6249 | CG4: =IF(CB4<=1.22, 20*CE4*CD4, 12.5*CE4*((CB4+0.305)/CB4)^2*CD4) -> 569.08835 | CH4: =CF4/CG4 -> 1.217078 | CJ4: 25 | CK4: 50 | CL4: =CG4 -> 569.08835 | CM4: =25.4 * (CK4/CL4) -> 2.2316394
Z5: 3 | AA5: 4.5 | AB5: 1.5 | AC5: 1.5 | AD5: 21 | AE5: =AE4+(AB5*AD5) -> 93 | AF5: =IF(AA5>AC5,(AA5-AC5)*9.81,0) -> 29.43 | AG5: =AE5-AF5 -> 63.57 | AH5: 0.3 | AI5: =IF(AA5<=9.15,(1-0.00765*AA5), IF(AA5<=23, (1.174-0.0267*AA5))) -> 0.965575 | AJ5: =0.65*AH5*(AE5/AG5)*AI5 -> 0.27545544 | AK5: 6.5 | AL5: =ROUND((10^2.24)/(AK5^2.56),6) -> 1.441922 | AM5: 29.55 | AN5: Silty Sand | AO5: SM | AP5: 34.5 | AQ5: =IF(AM5<=5, AP5, IF(AM5<35, EXP(1.76-(190/AM5^2))+(0.99+(AM5^1.5/1000))*AP5, 5+(1.2*AP5))) -> 44.372703 | AR5: =IF(OR(AO5="CL", AO5="CH", AO5="ML", AO5="MH", AO5="OL", AO5="OH", AO5="Pt", AO5="CL-ML"), "N/A (Cohesive)", SQRT(AP5/60)*100) -> 75.828754 | AS5: =IF(AR5<=40, 0.8, IF(AR5<=70, 0.7, 0.6)) -> 0.6 | AT5: =IF(OR(AS5="-", AS5=""), 1, MIN(1, (AG5/100)^(AS5-1))) -> 1 | AU5: =IF(OR(AS6="N/A (Cohesive)", AS6="-"), 1, IF(AG6/100 <= 3, 1, 1)) -> 1 | AV5: =IF(AQ5>=30, 0.6, (1/(34-AQ5))+(AQ5/135)+(50/((10*AQ5)+45)^2)-(1/200)) -> 0.6 | AW5: =((AV5*AL5*AT5*AU5)/AJ5) -> 3.1408099 | AX5: =IF(AW5>1, "NOT LIQUEFIABLE", "LIQUEFIABLE") -> NOT LIQUEFIABLE | AY5: =IF(AA5<20, 10-(0.5*AA5), 0) -> 7.75 | AZ5: =IF(AW5<1, 1-AW5, 0) -> 0 | BA5: =AB5*AY5*AZ5 -> 0 | BB5: =IF(BA5 > 15, "Very High", IF(BA5 > 5, "High", IF(BA5 > 0, "Low", "Very Low"))) -> Very Low | BX5: 3 | BY5: Silty Sand | BZ5: 4.5 | CA5: 34.5
BX6: 4 | BY6: Silty Sand | BZ6: 6 | CA6: 31.5
I7: DPWH BSDS (2013) | AQ7: NOTE: For soil layers with (𝑁1)60𝑐𝑠≥30, the Cyclic Resistance Ratio (CRR) is capped at a maximum value of 0.60. This limitation is applied because very dense sand is generally considered non-liquefiable under typical design earthquake conditions, in accordance with Idriss and Boulanger (2010) and NCEER guidelines. | BA7: NOTE: "The Liquefaction Potential Index (LPI) was determined following the method proposed by Iwasaki et al. (1978, 1982) and further developed for layer summation by Luna and Frost (1998)." | BX7: 5 | BY7: Silty Sand | BZ7: 7.5 | CA7: 35.25
A8: Sample | B8: D50 (mm) | C8: D10 (mm) | D8: Depth (m) | E8: Plasticity (%) | F8: Ground Water Level (m) | G8: Fines Content (%) | I8: D50 | J8: D10 | K8: Soil Layer is below water table and Soil Layer Depth < 20m | L8: Soil Layer Plasticity | M8: Assessment | S8: Stress Reduction Coefficient (rd) | BX8: 6 | BY8: Silty Sand | BZ8: 9 | CA8: 37.5
A9: 1 | B9: 0 | C9: 0 | D9: 1.5 | E9: - | F9: 1.5 | G9: 31.11 | I9: =IF(B9<10,"PASSED","NOT PASSED") -> PASSED | J9: =IF(C9<1,"PASSED","NOT PASSED") -> PASSED | K9: =IF(AND(D9>F9,D9<20),"PASSED","NOT PASSED") -> NOT PASSED | L9: =IF(OR(G9<35,E9<15),"PASSED","NOT PASSED") -> PASSED | M9: =IF(ISNUMBER(MATCH("NOT PASSED",I9:L9,0)),"No Potential","Potential") -> No Potential
A10: 2 | B10: 0 | C10: 0 | D10: 3 | E10: - | F10: 1.5 | G10: 25.77 | I10: =IF(B10<10,"PASSED","NOT PASSED") -> PASSED | J10: =IF(C10<1,"PASSED","NOT PASSED") -> PASSED | K10: =IF(AND(D10>=F10,D10<20),"PASSED","NOT PASSED") -> PASSED | L10: =IF(OR(G10<35,E10<15),"PASSED","NOT PASSED") -> PASSED | M10: =IF(ISNUMBER(MATCH("NOT PASSED",I10:L10,0)),"No Potential","Potential") -> Potential | CB10: SOIL BEARING CAPACITY BASED ON SPT-N VALUE (KPA) - Meyerhof (1974) | CJ10: SETTLEMENT BASED ON SPT-N VALUE - Meyerhof(1974)
A11: 3 | B11: 0 | C11: 0 | D11: 4.5 | E11: - | F11: 1.5 | G11: 29.55 | I11: =IF(B11<10,"PASSED","NOT PASSED") -> PASSED | J11: =IF(C11<1,"PASSED","NOT PASSED") -> PASSED | K11: =IF(AND(D11>=F11,D11<20),"PASSED","NOT PASSED") -> PASSED | L11: =IF(OR(G11<35,E11<15),"PASSED","NOT PASSED") -> PASSED | M11: =IF(ISNUMBER(MATCH("NOT PASSED",I11:L11,0)),"No Potential","Potential") -> Potential | CB11: Width (B) | CC11: Depth (D) | CD11: Depth Factor (Kd) | CE11: N-Value(ave) | CF11: Qu (KPa) | CG11: Qa (KPa) | CH11: FS | CJ11: Width (B) | CK11: Q-actual load (KPa) | CL11: N-Value(ave) | CM11: Settlement (mm)
BI12: Pre-Liquefaction Soil Bearing Capacity | CB12: 2 | CC12: 1.5 | CD12: =MIN(1.33, 1 + 0.33 * (CC12/CB12)) -> 1.2475 | CE12: =AVERAGEIFS($CA$3:$CA$8, $BZ$3:$BZ$8, ">=" & CC12,$BZ$3:$BZ$8, "<=" & (CC12 + 2 * CB12)) -> 29.75 | CF12: =(CE12/4) * 47.88 * CD12 -> 444.24411 | CG12: =IF(CB12<=1.22, 12*CE12*CD12, 8*CE12*((CB12+0.305)/CB12)^2*CD12) -> 394.36592 | CH12: =CF12/CG12 -> 1.1264769 | CJ12: =CB12 -> 2 | CK12: 50 | CL12: =CE12 -> 29.75 | CM12: =IF(CJ12<=1.22, (1.91*CK12)/(CL12*CD12), (2.84*CK12)/(CL12*CD12*((CJ12+0.305)/CJ12)^2)) -> 2.8805734
CB13: 2.5 | CC13: 1.5 | CD13: =MIN(1.33, 1 + 0.33 * (CC13/CB13)) -> 1.198 | CE13: =AVERAGEIFS($CA$3:$CA$8, $BZ$3:$BZ$8, ">=" & CC13,$BZ$3:$BZ$8, "<=" & (CC13 + 2 * CB13)) -> 30.1875 | CF13: =(CE13/4) * 47.88 * CD13 -> 432.89056 | CG13: =IF(CB13<=1.22, 12*CE13*CD13, 8*CE13*((CB13+0.305)/CB13)^2*CD13) -> 364.21654 | CH13: =CF13/CG13 -> 1.1885527 | CJ13: =CB13 -> 2.5 | CK13: 50 | CL13: =CE13 -> 30.1875 | CM13: =IF(CJ13<=1.22, (1.91*CK13)/(CL13*CD13), (2.84*CK13)/(CL13*CD13*((CJ13+0.305)/CJ13)^2)) -> 3.1190236
CB16: NO LIQUEFACTION
S18: Total Vertical Overburden Stress (𝜎)
S21: Effective Vertical Overburden Stress (𝜎′)
CB23: FORMULA IS IN ENGLISH UNIT
S32: Magnitude Correction Factor
CB44: According to the study by Fahad, Shakir, and Ali (2022), the Meyerhof (1974) method is the most accurate for predicting ultimate bearing capacity as it achieved the best convergence with actual field results by utilizing the correct influence zone depth.
S51: Overburden Correction Factor
S69: Sloping Ground Correction Factor
R137: Liquefaction Potential Index

Sheet LIQUEFACTION
AM1: Cyclic Strength Ratio (CSR) | BE1: The user provides this value
AT2: Sample | AU2: Depth (z) | AV2: Thickness(h) | AW2: GWL | AX2: Unit Weight (γ) | AY2: Total Stress (𝜎) | AZ2: Porepressure (𝑢) | BA2: Effective Stress (𝜎′) | BB2: Peak Ground Acceleration (a/g) | BC2: Stress Reduction Coefficient (rd) | BD2: CSR | BE2: Magnitude (Mw) | BF2: MSF/km | BG2: Fines Content | BH2: USCS | BI2: USCS Symbol | BJ2: N1(60) | BK2: (N1)60cs | BL2: Relative Density (Dr) % | BM2: f | BN2: k𝜎 | BO2: ka | BP2: CRR(7.5) | BQ2: FS | BR2: REMARK | BS2: Weighing Factor (wi) | BT2: Severity Factor (Fi) | BU2: LPI | BV2: Remarks
AT3: 1 | AU3: 1.5 | AV3: 1.5 | AW3: 1.5 | AX3: 21 | AY3: =AV3*AX3 -> 31.5 | AZ3: =IF(AU3>AW3,(AU3-AW3)*9.81,0) -> 0 | BA3: =AY3-AZ3 -> 31.5 | BB3: 0.3 | BC3: =IF(AU3<=9.15,(1-0.00765*AU3), IF(AU3<=23, (1.174-0.0267*AU3))) -> 0.988525 | BD3: =0.65*BB3*(AY3/BA3)*BC3 -> 0.19276238 | BE3: 6.5 | BF3: =ROUND((10^2.24)/(BE3^2.56),6) -> 1.441922 | BG3: 31.11 | BH3: Silty Sand | BI3: SM | BJ3: 22.5 | BK3: =IF(BG3<=5, BJ3, IF(BG3<35, EXP(1.76-(190/BG3^2))+(0.99+(BG3^1.5/1000))*BJ3, 5+(1.2*BJ3))) -> 30.955594 | BL3: =IF(OR(BI3="CL", BI3="CH", BI3="ML", BI3="MH", BI3="OL", BI3="OH", BI3="Pt", BI3="CL-ML"), "N/A (Cohesive)", SQRT(BJ3/60)*100) -> 61.237244 | BM3: =IF(BL3="N/A (Cohesive)", "-", IF(BL3<=40, 0.8, IF(BL3<=70, 0.7, 0.6))) -> 0.7 | BN3: =IF(OR(BM3="-", BM3=""), 1, MIN(1, (BA3/100)^(BM3-1))) -> 1 | BO3: =IF(OR(BM4="N/A (Cohesive)", BM4="-"), 1, IF(BA4/100 <= 3, 1, 1)) -> 1 | BP3: =IF(BK3>=30, 0.6, (1/(34-BK3))+(BK3/135)+(50/((10*BK3)+45)^2)-(1/200)) -> 0.6 | BQ3: =((BP3*BF3*BN3*BO3)/BD3) -> 4.488185 | BR3: =IF(BQ3>1, "NOT LIQUEFIABLE", "LIQUEFIABLE") -> NOT LIQUEFIABLE | BS3: =IF(AU3<20, 10-(0.5*AU3), 0) -> 9.25 | BT3: =IF(BQ3<1, 1-BQ3, 0) -> 0 | BU3: =AV3*BS3*BT3 -> 0 | BV3: =IF(BU3 > 15, "Very High", IF(BU3 > 5, "High", IF(BU3 > 0, "Low", "Very Low"))) -> Very Low
AT4: 2 | AU4: 3 | AV4: 1.5 | AW4: 1.5 | AX4: 20 | AY4: =AY3+(AV4*AX4) -> 61.5 | AZ4: =IF(AU4>AW4,(AU4-AW4)*9.81,0) -> 14.715 | BA4: =AY4-AZ4 -> 46.785 | BB4: 0.3 | BC4: =IF(AU4<=9.15,(1-0.00765*AU4), IF(AU4<=23, (1.174-0.0267*AU4))) -> 0.97705 | BD4: =0.65*BB4*(AY4/BA4)*BC4 -> 0.25044933 | BE4: 6.5 | BF4: =ROUND((10^2.24)/(BE4^2.56),6) -> 1.441922 | BG4: 25.77 | BH4: Silty Sand | BI4: SM | BJ4: 32.25 | BK4: =IF(BG4<=5, BJ4, IF(BG4<35, EXP(1.76-(190/BG4^2))+(0.99+(BG4^1.5/1000))*BJ4, 5+(1.2*BJ4))) -> 40.512631 | BL4: =IF(OR(BI4="CL", BI4="CH", BI4="ML", BI4="MH", BI4="OL", BI4="OH", BI4="Pt", BI4="CL-ML"), "N/A (Cohesive)", SQRT(BJ4/60)*100) -> 73.314391 | BM4: =IF(BL4<=40, 0.8, IF(BL4<=70, 0.7, 0.6)) -> 0.6 | BN4: =IF(OR(BM4="-", BM4=""), 1, MIN(1, (BA4/100)^(BM4-1))) -> 1 | BO4: =IF(OR(BM5="N/A (Cohesive)", BM5="-"), 1, IF(BA5/100 <= 3, 1, 1)) -> 1 | BP4: =IF(BK4>=30, 0.6, (1/(34-BK4))+(BK4/135)+(50/((10*BK4)+45)^2)-(1/200)) -> 0.6 | BQ4: =((BP4*BF4*BN4*BO4)/BD4) -> 3.4544041 | BR4: =IF(BQ4>1, "NOT LIQUEFIABLE", "LIQUEFIABLE") -> NOT LIQUEFIABLE | BS4: =IF(AU4<20, 10-(0.5*AU4), 0) -> 8.5 | BT4: =IF(BQ4<1, 1-BQ4, 0) -> 0 | BU4: =AV4*BS4*BT4 -> 0 | BV4: =IF(BU4 > 15, "Very High", IF(BU4 > 5, "High", IF(BU4 > 0, "Low", "Very Low"))) -> Very Low
AT5: 3 | AU5: 4.5 | AV5: 1.5 | AW5: 1.5 | AX5: 21 | AY5: =AY4+(AV5*AX5) -> 93 | AZ5: =IF(AU5>AW5,(AU5-AW5)*9.81,0) -> 29.43 | BA5: =AY5-AZ5 -> 63.57 | BB5: 0.3 | BC5: =IF(AU5<=9.15,(1-0.00765*AU5), IF(AU5<=23, (1.174-0.0267*AU5))) -> 0.965575 | BD5: =0.65*BB5*(AY5/BA5)*BC5 -> 0.27545544 | BE5: 6.5 | BF5: =ROUND((10^2.24)/(BE5^2.56),6) -> 1.441922 | BG5: 29.55 | BH5: Silty Sand | BI5: SM | BJ5: 34.5 | BK5: =IF(BG5<=5, BJ5, IF(BG5<35, EXP(1.76-(190/BG5^2))+(0.99+(BG5^1.5/1000))*BJ5, 5+(1.2*BJ5))) -> 44.372703 | BL5: =IF(OR(BI5="CL", BI5="CH", BI5="ML", BI5="MH", BI5="OL", BI5="OH", BI5="Pt", BI5="CL-ML"), "N/A (Cohesive)", SQRT(BJ5/60)*100) -> 75.828754 | BM5: =IF(BL5<=40, 0.8, IF(BL5<=70, 0.7, 0.6)) -> 0.6 | BN5: =IF(OR(BM5="-", BM5=""), 1, MIN(1, (BA5/100)^(BM5-1))) -> 1 | BO5: =IF(OR(BM6="N/A (Cohesive)", BM6="-"), 1, IF(BA6/100 <= 3, 1, 1)) -> 1 | BP5: =IF(BK5>=30, 0.6, (1/(34-BK5))+(BK5/135)+(50/((10*BK5)+45)^2)-(1/200)) -> 0.6 | BQ5: =((BP5*BF5*BN5*BO5)/BD5) -> 3.1408099 | BR5: =IF(BQ5>1, "NOT LIQUEFIABLE", "LIQUEFIABLE") -> NOT LIQUEFIABLE | BS5: =IF(AU5<20, 10-(0.5*AU5), 0) -> 7.75 | BT5: =IF(BQ5<1, 1-BQ5, 0) -> 0 | BU5: =AV5*BS5*BT5 -> 0 | BV5: =IF(BU5 > 15, "Very High", IF(BU5 > 5, "High", IF(BU5 > 0, "Low", "Very Low"))) -> Very Low
AC7: DPWH BSDS (2013) | BK7: NOTE: For soil layers with (𝑁1)60𝑐𝑠≥30, the Cyclic Resistance Ratio (CRR) is capped at a maximum value of 0.60. This limitation is applied because very dense sand is generally considered non-liquefiable under typical design earthquake conditions, in accordance with Idriss and Boulanger (2010) and NCEER guidelines. | BU7: NOTE: "The Liquefaction Potential Index (LPI) was determined following the method proposed by Iwasaki et al. (1978, 1982) and further developed for layer summation by Luna and Frost (1998)."
U8: Sample | V8: D50 (mm) | W8: D10 (mm) | X8: Depth (m) | Y8: Plasticity (%) | Z8: Ground Water Level (m) | AA8: Fines Content (%) | AC8: D50 | AD8: D10 | AE8: Soil Layer is below water table and Soil Layer Depth < 20m | AF8: Soil Layer Plasticity | AG8: Assessment | AM8: Stress Reduction Coefficient (rd)
U9: 1 | V9: 0 | W9: 0 | X9: 1.5 | Y9: - | Z9: 1.5 | AA9: 31.11 | AC9: =IF(V9<10,"PASSED","NOT PASSED") -> PASSED | AD9: =IF(W9<1,"PASSED","NOT PASSED") -> PASSED | AE9: =IF(AND(X9>Z9,X9<20),"PASSED","NOT PASSED") -> NOT PASSED | AF9: =IF(OR(AA9<35,Y9<15),"PASSED","NOT PASSED") -> PASSED | AG9: =IF(ISNUMBER(MATCH("NOT PASSED",AC9:AF9,0)),"No Potential","Potential") -> No Potential
U10: 2 | V10: 0 | W10: 0 | X10: 3 | Y10: - | Z10: 1.5 | AA10: 25.77 | AC10: =IF(V10<10,"PASSED","NOT PASSED") -> PASSED | AD10: =IF(W10<1,"PASSED","NOT PASSED") -> PASSED | AE10: =IF(AND(X10>=Z10,X10<20),"PASSED","NOT PASSED") -> PASSED | AF10: =IF(OR(AA10<35,Y10<15),"PASSED","NOT PASSED") -> PASSED | AG10: =IF(ISNUMBER(MATCH("NOT PASSED",AC10:AF10,0)),"No Potential","Potential") -> Potential
U11: 3 | V11: 0 | W11: 0 | X11: 4.5 | Y11: - | Z11: 1.5 | AA11: 29.55 | AC11: =IF(V11<10,"PASSED","NOT PASSED") -> PASSED | AD11: =IF(W11<1,"PASSED","NOT PASSED") -> PASSED | AE11: =IF(AND(X11>=Z11,X11<20),"PASSED","NOT PASSED") -> PASSED | AF11: =IF(OR(AA11<35,Y11<15),"PASSED","NOT PASSED") -> PASSED | AG11: =IF(ISNUMBER(MATCH("NOT PASSED",AC11:AF11,0)),"No Potential","Potential") -> Potential
AM18: Total Vertical Overburden Stress (𝜎)
AM21: Effective Vertical Overburden Stress (𝜎′)
AM32: Magnitude Correction Factor
AM51: Overburden Correction Factor

Sheet Without Liq
CB1: SOIL BEARING CAPACITY BASED ON SPT-N VALUE (KPA) - Bowles (1988) | CJ1: SETTLEMENT BASED ON SPT-N VALUE - 25mm - Bowles(1988)
BX2: Sample | BY2: USCS | BZ2: Depth | CA2: (N1)60 | CB2: Width (B) | CC2: Depth (D) | CD2: Depth Factor (Kd) | CE2: N-Value(ave) | CF2: Qu (KPa) | CG2: Qa (KPa) | CH2: FS | CJ2: Si | CK2: Q-actual load (KPa) | CL2: Qa (KPa) | CM2: Settlement (mm)
BX3: 1 | BY3: Silty Sand | BZ3: 1.5 | CA3: 22.5 | CB3: 2 | CC3: 1.5 | CD3: =MIN(1.33, 1 + 0.33 * (CC3/CB3)) -> 1.2475 | CE3: =AVERAGEIFS($CA$3:$CA$8, $BZ$3:$BZ$8, ">=" & CC3,$BZ$3:$BZ$8, "<=" & (CC3 + 2 * CB3)) -> 29.75 | CF3: =(CE3/2.5)*47.88*CD3 -> 710.79057 | CG3: =IF(CB3<=1.22, 20*CE3*CD3, 12.5*CE3*((CB3+0.305)/CB3)^2*CD3) -> 616.19675 | CH3: =CF3/CG3 -> 1.1535124 | CJ3: 25 | CK3: 50 | CL3: =CG3 -> 616.19675 | CM3: =25.4 * (CK3/CL3) -> 2.06103
BX4: 2 | BY4: Silty Sand | BZ4: 3 | CA4: 32.25 | CB4: 2.5 | CC4: 1.5 | CD4: =MIN(1.33, 1 + 0.33 * (CC4/CB4)) -> 1.198 | CE4: =AVERAGEIFS($CA$3:$CA$8, $BZ$3:$BZ$8, ">=" & CC4,$BZ$3:$BZ$8, "<=" & (CC4 + 2 * CB4)) -> 30.1875 | CF4: =(CE4/2.5)*47.88*CD4 -> 692.6249 | CG4: =IF(CB4<=1.22, 20*CE4*CD4, 12.5*CE4*((CB4+0.305)/CB4)^2*CD4) -> 569.08835 | CH4: =CF4/CG4 -> 1.217078 | CJ4: 25 | CK4: 50 | CL4: =CG4 -> 569.08835 | CM4: =25.4 * (CK4/CL4) -> 2.2316394
BX5: 3 | BY5: Silty Sand | BZ5: 4.5 | CA5: 34.5
BX6: 4 | BY6: Silty Sand | BZ6: 6 | CA6: 31.5
BX7: 5 | BY7: Silty Sand | BZ7: 7.5 | CA7: 35.25
BX8: 6 | BY8: Silty Sand | BZ8: 9 | CA8: 37.5
CB10: SOIL BEARING CAPACITY BASED ON SPT-N VALUE (KPA) - Meyerhof (1974) | CJ10: SETTLEMENT BASED ON SPT-N VALUE - Meyerhof(1974)
CB11: Width (B) | CC11: Depth (D) | CD11: Depth Factor (Kd) | CE11: N-Value(ave) | CF11: Qu (KPa) | CG11: Qa (KPa) | CH11: FS | CJ11: Width (B) | CK11: Q-actual load (KPa) | CL11: N-Value(ave) | CM11: Settlement (mm)
CB12: 2 | CC12: 1.5 | CD12: =MIN(1.33, 1 + 0.33 * (CC12/CB12)) -> 1.2475 | CE12: =AVERAGEIFS($CA$3:$CA$8, $BZ$3:$BZ$8, ">=" & CC12,$BZ$3:$BZ$8, "<=" & (CC12 + 2 * CB12)) -> 29.75 | CF12: =(CE12/4) * 47.88 * CD12 -> 444.24411 | CG12: =IF(CB12<=1.22, 12*CE12*CD12, 8*CE12*((CB12+0.305)/CB12)^2*CD12) -> 394.36592 | CH12: =CF12/CG12 -> 1.1264769 | CJ12: =CB12 -> 2 | CK12: 50 | CL12: =CE12 -> 29.75 | CM12: =IF(CJ12<=1.22, (1.91*CK12)/(CL12*CD12), (2.84*CK12)/(CL12*CD12*((CJ12+0.305)/CJ12)^2)) -> 2.8805734
CB13: 2.5 | CC13: 1.5 | CD13: =MIN(1.33, 1 + 0.33 * (CC13/CB13)) -> 1.198 | CE13: =AVERAGEIFS($CA$3:$CA$8, $BZ$3:$BZ$8, ">=" & CC13,$BZ$3:$BZ$8, "<=" & (CC13 + 2 * CB13)) -> 30.1875 | CF13: =(CE13/4) * 47.88 * CD13 -> 432.89056 | CG13: =IF(CB13<=1.22, 12*CE13*CD13, 8*CE13*((CB13+0.305)/CB13)^2*CD13) -> 364.21654 | CH13: =CF13/CG13 -> 1.1885527 | CJ13: =CB13 -> 2.5 | CK13: 50 | CL13: =CE13 -> 30.1875 | CM13: =IF(CJ13<=1.22, (1.91*CK13)/(CL13*CD13), (2.84*CK13)/(CL13*CD13*((CJ13+0.305)/CJ13)^2)) -> 3.1190236
CB16: NO LIQUEFACTION
CB23: FORMULA IS IN ENGLISH UNIT
CB44: According to the study by Fahad, Shakir, and Ali (2022), the Meyerhof (1974) method is the most accurate for predicting ultimate bearing capacity as it achieved the best convergence with actual field results by utilizing the correct influence zone depth.

Sheet With Liq
A1: Foundation Width (B) | B1: 2
A2: Foundation Length (L) | B2: 2
A3: Embedment Depth (Df) | B3: 1.5
A4: Buoyant Unit Weight of Soil (γ′) | B4: 11.22
A5: Initial Soil Friction Angle (ϕ′) | B5: 30
A6: Thickness of Liquefiable Layer (Z liq) | B6: =SUMIFS(C35:Z35, C34:Z34, ">=" & B3, C36:Z36, "Liquifiable") -> 0
A7: Modified SPT Number (N1)60 | B7: 22.5
A8: Fine Content (FC) | B8: 31.11
A9: Actual Building Contact Pressure qbuild​ | B9: =Summary!CK3 -> 50
A10: PRE-CALCULATIONS (Intermediate Values)
A11: Aspect Factor (α) | B11: =1.5 - 0.5 * (B1 / B2) -> 1
A12: Overburden (qˉ​) | B12: =B4 * B3 -> 16.83
A13: ΔN1​ | B13: =IF(B8>=75, 5, IF(B8>=50, 4, IF(B8>=25, 2, 1))) -> 2
A14: (N1​)60,cs​ | B14: =B7 + B13 -> 24.5
A15: Sr​/σv0′​ | B15: =EXP(((B14/16)+((B14/16)^2)/21.2)^3 - 3) -> 4.1615626
A16: Sr,base​ | B16: =B15 * (B12 + (B11 * B1 * B4)) -> 163.42456
A17: Sr,avg​ | B17: =B15 * (B12 + (B11 * B1 * B4 / 2)) -> 116.73183
A18: Lateral Failure Calculation (qu1​):
A19: Degradation Factor (1−ru​) | B19: =IF(B6=0, 1, IF(B6 <= (B11*B1), (2-0.03*B12)*(B6/(B11*B1))^(0.3-0.006*B12)*B1^(0.007*B12-0.7*(B6/(B11*B1))), (2-0.03*B12)*(B6/(B11*B1))^-0.85*B1^(0.007*B12-0.7))) -> 1
A20: Lateral Bearing Capacity (qu1​) | B20: =B11 * (30 + 0.3 * B12) * (TAN(RADIANS(45 + DEGREES(ATAN(B19 * TAN(RADIANS(B5)))) / 2))^2) -> 105.147 | J20: `
A21: Punching Failure Calculation (qu2​):
A22: B22 (Punching Degradation Factor) | B22: =0.1 + 3 * B15 -> 12.584688
A23: B23 (Punching Bearing Capacity qu2​) | B23: =B11 * (PI() + 2 * (1 + 0.2 * B11 * B1 / B2)) * B16 + 2 * B11 * (1 + B11 * B1 / B2) * B17 - (B11^2) * B1 * B4 * B22 -> 1090.1593
A24: FINAL RESULTS AND INTERPRETATION
A25: FINAL LIQUEFIED CAPACITY (qu​) | B25: =IF(B6=0, B30, IF(B6 <= (B11 * B1), B20, MIN(B20, B23))) -> 639.30454
A26: STRENGTH STATUS | B26: =IF(B9/B25 > 1, "FAILURE (Settlement > 10%B)", "STABLE") -> STABLE
A27: CAPACITY REDUCTION | B27: =(B25/B30)*100 -> 100
A28: Nq​ Factor) | B28: =EXP(PI()*TAN(RADIANS(B5)))*(TAN(RADIANS(45+B5/2))^2) -> 18.401122
A29: Nγ​ Factor | B29: =2*(B28+1)*TAN(RADIANS(B5)) -> 22.402486
A30: qstatic​ - Orignal Strength | B30: =(B12*B28*(1+(B1/B2)*TAN(RADIANS(B5)))) + (0.5*B4*B1*B29*(1-0.4*(B1/B2))) -> 639.30454
A31: Post-Liquefaction Bearing Capacity (qu​) | B31: =IF(B6=0, B30, MIN(B20, B23)) -> 639.30454
A32: Post-Liquefaction Total Settlement (S) | B32: =MAX(0, B1 * ((0.1746 * (B9/B31 - 0.25)) / (6.1775 - 6.6502 * (B9/B31 - 0.25)))) * 1000 -> 0
A33: SERVICEABLITY STATUS | B33: =IF(B32/B1 > 0.1, "FAILED (Settlement > 10%B)", "STABLE") -> STABLE
A34: Depth | B34: =Summary!D9 -> 1.5 | C34: =Summary!AA4 -> 3 | D34: =Summary!AA5 -> 4.5
A35: Thickness | B35: =Summary!AB3 -> 1.5 | C35: =Summary!AB4 -> 1.5 | D35: =Summary!AB5 -> 1.5
A36: Status | B36: =Summary!AX3 -> NOT LIQUEFIABLE | C36: =Summary!AX4 -> NOT LIQUEFIABLE | D36: =Summary!AX5 -> NOT LIQUEFIABLE
A38: LIQUEFACTION

Sheet 0m-1.5m
A1: Municipality | B1: Borehole ID | C1: Sample No. | D1: Latitude | E1: Longitude | F1: Elevation | G1: Soil/Rock Description | H1: USCS Symbol | I1: Fault Distance (km) | J1: Ground Water Table | K1: SPT N-Value | L1: Plasticity Index (PI) | M1: Natural Water Content (ω) | N1: Mean Particle Size (D50) (mm) | O1: Groundwater Level (m) | P1: Unit Weight (γ) | Q1: Foundation Width (B) | R1: Foundation Depth (D) | S1: Internal Friction Angle | T1: Length-to-width ratio (L/B) | U1: Corrected SPT-N Value (N1(60)) | V1: Fines Content | W1: Effective Overburden Presssure | X1: Total Overburden Pressure | Y1: Relative Density | Z1: Peak Ground Acceleration | AA1: Cyclic Stress Ratio (CSR) | AB1: Elastic Modulus (Es) (MN/
A2: Anao | B2: BH-1 | C2: SS-1 | D2: 15.715506° | E2: 120.623904° | F2: 16.78 | G2: Silty Sand | H2: SM | I2: 26.3 | J2: 28.5 | K2: 8 | M2: 0.1762 | N2: 0.2 | O2: 28.5 | P2: 18 | Q2: 30 | R2: 6 | S2: 0.2854 | U2: 0.4g (RP: 500-yr; STIFF Soil) | W2: 3000 to 5000
A3: Anao | B3: BH-2 | C3: SS-1 | D3: 15.759126° | E3: 120.600236° | F3: 27.15 | G3: Silty Clay | H3: CH | I3: 30.8 | J3: 1.5 | K3: 5 | L3: 0.321 | M3: 0.3477 | N3: 0 | O3: 1.5 | P3: 17 | Q3: 18 | R3: 3.75 | S3: 0.8585 | U3: 0.3g (RP: 500-yr; STIFF Soil) | W3: 6000
A4: Anao | B4: BH-3 | C4: SS-1 | D4: 15.759537° | E4: 120.600182° | F4: 23.49 | G4: Silty Clay | H4: CH | I4: 30.8 | J4: 1.5 | K4: 9 | L4: 0.3584 | M4: 0.3468 | N4: 0 | O4: 1.5 | P4: 17 | Q4: 19.5 | R4: 6.75 | S4: 0.8409 | U4: 0.3g (RP: 500-yr; STIFF Soil) | W4: 13000
A5: Bamban | B5: BH-4 | C5: SS-1 | D5: 15.27346° | E5: 120.56187° | F5: 80.45 | G5: Fat Clay with Sand | H5: CH | I5: 19.8 | K5: 17 | L5: 0.3 | M5: 0.4056 | P5: 17.1-19.2 | Q5: 31-40 | S5: 0.845 | U5: 0.4g | V5: 0.129
A6: Camiling | B6: BH-5 | C6: SS-1 | D6: 15.686632° | E6: 120.412972° | F6: 16.48 | G6: Clayey Silt | H6: MH | I6: 7.6 | J6: 4.5 | K6: 18 | L6: 0.23 | M6: 0.3425 | O6: 4.5 | P6: 17 | Q6: 25 | S6: 0.651 | U6: 0.4g (RP: 500-yr; STIFF Soil) | W6: 15
A7: Camiling | B7: BH-6 | C7: SS-1 | D7: 15.686638° | E7: 120.413130° | F7: 16.78 | G7: Clayey Silt | H7: MH | I7: 7.6 | J7: 5 | K7: 16 | L7: 0.244 | M7: 0.3471 | O7: 5 | P7: 17.1 | Q7: 25 | S7: 0.652 | U7: 0.4g (RP: 500-yr; STIFF Soil) | W7: 15
A8: Camiling | B8: BH-7 | C8: SS-1 | D8: 15.686652° | E8: 120.412968° | F8: 16.17 | G8: Brown, Clayey Silt of medium plasticity | H8: MH | I8: 8.3 | J8: 6 | K8: 11 | L8: 0.236 | M8: 0.3586 | O8: 6 | P8: 20 | Q8: 27.5 | S8: 0.671 | U8: 0.4g | W8: ########
A9: Camiling | B9: BH-8 | C9: SS-1 | D9: 15.686296° | E9: 120.412971° | F9: 17.09 | G9: Brown, Clayey Silt of medium plasticity | H9: MH | I9: 8.3 | J9: 7 | K9: 10 | L9: 0.273 | M9: 0.3735 | O9: 7 | P9: 20 | Q9: 27.5 | S9: 0.638 | U9: 0.4g | W9: ########
A10: Camiling | B10: BH-9 | C10: SS-1 | D10: 15.732336° | E10: 120.434617° | F10: 11.3 | G10: Clayey Silt | H10: MH | I10: 11.3 | J10: 4.3 | K10: 9 | L10: 0.263 | M10: 0.3329 | N10: 0 | O10: 4.3 | P10: 17 | Q10: 20 | R10: 7 | S10: 0.671 | U10: 0.2g (RP:500-yr; ROCK SITE) | W10: 10
A11: Camiling | B11: BH-10 | C11: SS-1 | D11: 15.743831° | E11: 120.443005° | F11: 25.93 | G11: Sandy Silt | H11: ML | I11: 12.5 | J11: Not Encountered | K11: 25 | L11: 0.148 | M11: 0.2455 | N11: 0 | O11: N.E. | P11: 23 | Q11: 30 | R11: 19 | S11: 0.574 | U11: 0.3g (RP:500-yr; STIFF SOIL) (ROCK SITE) | W11: 300
A12: Camiling | B12: BH-11 | C12: SS-1 | D12: 15.743915° | E12: 120.443051° | F12: 26.84 | G12: Sandy Silt | H12: ML | I12: 12.5 | J12: N.E. | K12: 24 | L12: 0.145 | M12: 0.2575 | N12: 0 | O12: N.E. | P12: 23 | Q12: 30 | R12: 18 | S12: 0.552 | U12: 0.3g (RP:500-yr; STIFF SOIL) (ROCK SITE) | W12: 300
A13: Camiling | B13: BH-12 | C13: SS-1 | D13: 15.656521° | E13: 120.400915° | F13: 18.92 | G13: Sandy Silt | H13: ML | I13: 4.8 | J13: 6 | K13: 15 | L13: 0.15 | M13: 0.2703 | O13: 6 | P13: 17.7 | Q13: 22.5 | R13: 11 | S13: 0.58 | U13: 0.4g | W13: 12
A14: Camiling | B14: BH-13 | C14: SS-1 | D14: 15.645886° | E14: 120.388381° | F14: 33.95 | G14: Gray, Clayey Sand | H14: SC | I14: 3 | J14: 4 | K14: 27 | L14: 0.22 | M14: 0.232 | O14: 4 | P14: 20 | Q14: 36 | S14: 0.2999 | U14: 0.4g | W14: 30
A15: Gerona | B15: BH-14 | C15: SS-1 | D15: 15.635467° | E15: 120.624711° | F15: 24.4 | G15: Silty Sand | H15: SM | I15: 19 | J15: 7.5 | K15: 21 | M15: 0.1643 | N15: 0 | O15: 7.5 | P15: 20 | Q15: 30-32 | R15: 16 | S15: 0.238 | U15: 0.3g (RP: 500-yr; STIFF Soil) | W15: 15000
A16: Gerona | B16: BH-15 | C16: SS-1 | D16: 15.635408° | E16: 120.624588° | F16: 23.79 | G16: Silty Sand | H16: SM | I16: 19 | J16: 7.5 | K16: 21 | M16: 0.1482 | N16: 0 | O16: 7.5 | P16: 21 | Q16: 30-32 | R16: 16 | S16: 0.269 | U16: 0.3g (RP: 500-yr; STIFF Soil) | W16: 15000
A17: Gerona | B17: BH-16 | C17: SS-1 | D17: 15.555744° | E17: 120.600555° | F17: 31.11 | G17: Sandy Silt | H17: ML | I17: 11.3 | J17: 3 | K17: 10 | L17: 0.17 | M17: 0.2849 | N17: 0 | O17: 3 | P17: 18 | Q17: 20 | R17: 8 | S17: 0.539 | U17: 0.3g (RP: 500-yr; STIFF Soil) | W17: 10000
A18: Gerona | B18: BH-17 | C18: SS-1 | D18: 15.555718° | E18: 120.600598° | F18: 31.11 | G18: Sandy Silt | H18: ML | I18: 11.3 | J18: 3 | K18: 7 | L18: 0.16 | M18: 0.2599 | N18: 0 | O18: 3 | P18: 18 | Q18: 20 | R18: 5 | S18: 0.568 | U18: 0.3g (RP: 500-yr; STIFF Soil) | W18: 10000
A19: Gerona | B19: BH-18 | C19: SS-1 | D19: 15.592509° | E19: 120.620622° | F19: 31.41 | G19: Sandy Silt | H19: ML | I19: 15.5 | J19: 3 | K19: 17 | L19: 0.182 | M19: 0.252 | N19: 0 | O19: 3 | P19: 18 | Q19: 22.5 | R19: 13 | S19: 0.565 | U19: 0.3g (RP: 500-yr; STIFF Soil) | W19: 12000
A20: Gerona | B20: BH-19 | C20: SS-1 | D20: 15.592510° | E20: 120.620552° | F20: 31.4 | G20: Silty Sand | H20: SM | I20: 15.5 | J20: 3 | K20: 14 | M20: 0.1717 | N20: 0 | O20: 3 | P20: 20 | Q20: 30-32 | R20: 11 | S20: 0.219 | U20: 0.3g (RP: 500-yr; STIFF Soil) | W20: 15000
A21: Gerona | B21: BH-20 | C21: SS-1 | D21: 15.556476° | E21: 120.573764° | F21: 31.41 | G21: Silty Sand | H21: SM | I21: 9 | J21: N.E | K21: 12 | M21: 0.1768 | N21: 0 | O21: N.E | P21: 19 | Q21: 27.5-30 | R21: 9 | S21: 0.256 | U21: 0.3g (RP: 500-yr; STIFF Soil) | W21: 10000
A22: Gerona | B22: BH-21 | C22: SS-1 | D22: 15.556501° | E22: 120.573845° | F22: 31.41 | G22: Silty Sand | H22: SM | I22: 9 | J22: N.E | K22: 12 | M22: 0.2016 | N22: 0 | O22: N.E | P22: 19 | Q22: 27.5-30 | R22: 9 | S22: 0.231 | U22: 0.3g (RP: 500-yr; STIFF Soil) | W22: 10000
A23: Gerona | B23: BH-22 | C23: SS-1 | D23: 15.578777° | E23: 120.573149° | F23: 28.06 | G23: Silty Sand | H23: SM | I23: 11.1 | J23: 12 | K23: 35 | M23: 0.2154 | N23: 0 | O23: 12 | P23: 20 | Q23: 32-35 | R23: 26.25 | S23: 0.2085 | U23: 0.3g (RP: 500-yr; STIFF Soil) | W23: 20000
A24: Gerona | B24: BH-23 | C24: SS-1 | D24: 15.578761° | E24: 120.573483° | F24: 28.98 | G24: Silty Sand | H24: SM | I24: 11.1 | J24: 4.5 | K24: 26 | M24: 0.1705 | N24: 0 | O24: 4.5 | P24: 21 | Q24: 30-32 | R24: 19.5 | S24: 0.3 | U24: 0.3g (RP: 500-yr; STIFF Soil) | W24: 15000
A25: Gerona | B25: BH-24 | C25: SS-1 | D25: 15.600169° | E25: 120.544751° | F25: 22.57 | G25: Clayey Silt | H25: MH | I25: 11.1 | J25: N.E | K25: 24 | L25: 0.26 | M25: 0.3478 | N25: 0 | O25: N.E | P25: 17 | Q25: 25 | R25: 18 | S25: 0.679 | U25: 0.3g (RP: 500-yr; STIFF Soil) | W25: 15000
A26: Gerona | B26: BH-25 | C26: SS-1 | D26: 15.600168° | E26: 120.544618° | F26: 22.57 | G26: Clayey Silt | H26: MH | I26: 11.1 | J26: N.E | K26: 22 | L26: 0.26 | M26: 0.3389 | N26: 0 | O26: N.E | P26: 17 | Q26: 25 | R26: 17 | S26: 0.672 | U26: 0.3g (RP: 500-yr; STIFF Soil) | W26: 15000
A27: Gerona | B27: BH-26 | C27: SS-1 | D27: 15.589244° | E27: 120.597051° | F27: 29.46 | G27: Silty Sand | H27: SM | I27: 13.3 | J27: 2.5 | K27: 21 | M27: 0.1556 | N27: 0 | O27: 2.5 | P27: 0 | Q27: 30-32 | R27: 16 | S27: 0.288 | U27: 0.3g (RP: 500-yr; STIFF Soil) | W27: 15000
A28: Gerona | B28: BH-27 | C28: SS-1 | D28: 15.58917° | E28: 120.597011° | F28: 29.16 | G28: Silty Sand | H28: SM | I28: 13.3 | J28: 2.5 | K28: 14 | M28: 0.1676 | N28: 0 | O28: 2.5 | P28: 0 | Q28: 30-32 | R28: 11 | S28: 0.297 | U28: 0.3g (RP: 500-yr; STIFF Soil) | W28: 15000
A29: Gerona | B29: BH-28 | C29: SS-1 | D29: 15.620661° | E29: 120.500156° | F29: 29.58 | G29: Sandy Silt | H29: ML | I29: 11 | J29: 3 | K29: 35 | L29: 0.19 | M29: 0.2279 | N29: 0 | O29: 3 | P29: 19 | Q29: 12 | R29: 26 | S29: 0.544 | U29: 0.3g (RP: 500-yr; STIFF Soil) | W29: 15000
A30: Gerona | B30: BH-29 | C30: SS-1 | D30: 15.620647° | E30: 120.500056° | F30: 28.67 | G30: Sandy Silt | H30: ML | I30: 11 | J30: 2.37 | K30: 30 | L30: 0.16 | M30: 0.2796 | N30: 0 | O30: 2.37 | P30: 18 | Q30: 12 | R30: 23 | S30: 0.521 | U30: 0.3g (RP: 500-yr; STIFF Soil) | W30: 15000
A31: Gerona | B31: BH-30 | C31: SS-1 | D31: 15.598641° | E31: 120.517534° | F31: 58.57 | G31: Sandy Silt | H31: ML | I31: 10.2 | J31: 7 | K31: 58 | L31: 17 | M31: 2.2822 | N31: 0 | O31: 7 | P31: 18 | Q31: 27.5 | R31: 43.5 | S31: 0.53 | U31: 0.3g (RP: 500-yr; STIFF Soil, 0.3g (RP: 500-yr; ROCK Site) | W31: 20000
A32: Gerona | B32: BH-31 | C32: SS-1 | D32: 15.598293° | E32: 120.517626° | F32: 49.43 | G32: Sandy Silt | H32: ML | I32: 10.2 | J32: 12 | K32: 56 | L32: 14 | M32: 0.2765 | N32: 0 | O32: 12 | P32: 18 | Q32: 27.5 | R32: 42 | S32: 0.57 | U32: 0.3g (RP: 500-yr; STIFF Soil, 0.3g (RP: 500-yr; ROCK Site) | W32: 20000
A33: Gerona | B33: BH-32 | C33: SS-1 | D33: 15.555633° | E33: 120.608133° | F33: 30.8 | G33: Silty Clay | H33: CH | I33: 12 | J33: 2 | K33: 12 | L33: 34 | M33: 0.3222 | N33: 0 | O33: 2 | P33: 17 | Q33: 20 | R33: 9 | S33: 0.85 | U33: 0.3g (RP: 500-yr; STIFF Soil) | W33: 25000
A34: Gerona | B34: BH-33 | C34: SS-1 | D34: 15.555650° | E34: 120.608052° | F34: 30.8 | G34: Silty Clay | H34: CH | I34: 12 | J34: 2 | K34: 11 | L34: 32 | M34: 0.3568 | N34: 0 | O34: 2 | P34: 17 | Q34: 19.5 | R34: 8.25 | S34: 0.84 | U34: 0.3g (RP: 500-yr; STIFF Soil) | W34: 13000
A35: Gerona | B35: BH-34 | C35: SS-1 | D35: 15.602424° | E35: 120.593012° | F35: 32.02 | G35: Silty Sand | H35: SM | I35: 11.1 | J35: 4.5 | K35: 27 | M35: 0.1814 | N35: 0 | O35: 4.5 | P35: 21 | Q35: 30-32 | R35: 20 | S35: 0.27 | U35: 0.3g (RP: 500-yr; STIFF Soil) | W35: 15000
A36: Gerona | B36: BH-35 | C36: SS-1 | D36: 15.602593° | E36: 120.593001° | F36: 32.63 | G36: Silty Sand | H36: SM | I36: 11.1 | J36: 4.5 | K36: 21 | M36: 0.1698 | N36: 0 | O36: 4.5 | P36: 0 | Q36: 30-32 | R36: 16 | S36: 0.25 | U36: 0.3g (RP: 500-yr; STIFF Soil) | W36: 15000
A37: Moncada | B37: BH-36 | C37: SS-1 | D37: 15.745085° | E37: 120.576019° | F37: 22.3 | G37: Sandy Silt | H37: ML | I37: 26.5 | J37: 2 | K37: 11 | L37: 0.16 | M37: 0.2762 | O37: 2 | P37: 20 | Q37: 27.5 | S37: 0.55 | U37: 0.3g | W37: ########
A38: Moncada | B38: BH-37 | C38: SS-1 | D38: 15.744907° | E38: 120.576261° | F38: 23.2 | G38: Sandy Silt | H38: ML | I38: 26.5 | J38: 2 | K38: 13 | L38: 0.17 | M38: 0.2547 | O38: 2 | P38: 20 | Q38: 27.5 | S38: 0.52 | U38: 0.3g | W38: ########
A39: Moncada | B39: BH-38 | C39: SS-1 | D39: 15.769566° | E39: 120.575766° | F39: 20.4 | G39: Sandy Silt | H39: ML | I39: 27 | J39: 1.05 | K39: 8 | L39: 0.151 | M39: 0.2729 | O39: 1.05 | P39: 20 | Q39: 27.5 | S39: 0.5198 | W39: ########
A40: Moncada | B40: BH-39 | C40: SS-1 | D40: 15.769692° | E40: 120.575525° | F40: 19.8 | G40: Sandy Silt | H40: ML | I40: 27 | J40: 1 | K40: 14 | L40: 0.1309 | M40: 0.2166 | O40: 1 | P40: 20 | Q40: 27.5 | S40: 0.512 | W40: ########
...

Sheet 1.5m-3.0m
A1: Municipality | B1: Borehole ID | C1: Sample No. | D1: Latitude | E1: Longitude | F1: Elevation | G1: Soil/Rock Description | H1: USCS Symbol | I1: Fault Distance (km) | J1: Ground Water Table | K1: SPT N-Value | L1: Plasticity Index (PI) | M1: Natural Water Content (ω) | N1: Mean Particle Size (D50) (mm) | O1: Groundwater Level (m) | P1: Unit Weight (γ) | Q1: Foundation Width (B) | R1: Foundation Depth (D) | S1: Internal Friction Angle | T1: Length-to-width ratio (L/B) | U1: Corrected SPT-N Value (N1(60)) | V1: Fines Content | W1: Effective Overburden Presssure | X1: Total Overburden Pressure | Y1: Relative Density | Z1: Peak Ground Acceleration | AA1: Cyclic Stress Ratio (CSR) | AB1: Elastic Modulus (Es) (MN/
A2: Anao | B2: BH-1 | C2: SS-2 | D2: 15.715506° | E2: 120.623904° | F2: 15.28 | G2: Silty Sand | H2: SM | I2: 26.3 | J2: 28.5 | K2: 13 | M2: 0.1716 | N2: 0.2 | O2: 28.5 | P2: 18 | Q2: 30 | R2: 9.75 | S2: 0.2914 | U2: 0.4g (RP: 500-yr; STIFF Soil) | W2: 3000 to 5000
A3: Anao | B3: BH-2 | C3: SS-2 | D3: 15.759126° | E3: 120.600236° | F3: 25.65 | G3: Silty Clay | H3: CH | I3: 30.8 | J3: 1.5 | K3: 8 | L3: 0.3088 | M3: 0.3143 | N3: 0 | O3: 1.5 | P3: 17 | Q3: 19.5 | R3: 6 | S3: 0.8819 | U3: 0.3g (RP: 500-yr; STIFF Soil) | W3: 13000
A4: Anao | B4: BH-3 | C4: SS-2 | D4: 15.759537° | E4: 120.600182° | F4: 21.99 | G4: Silty Clay | H4: CH | I4: 30.8 | J4: 1.5 | K4: 13 | L4: 0.3014 | M4: 0.3161 | N4: 0 | O4: 1.5 | P4: 17 | Q4: 20 | R4: 9.75 | S4: 0.8269 | U4: 0.3g (RP: 500-yr; STIFF Soil) | W4: 25000
A5: Bamban | B5: BH-4 | C5: SS-2 | D5: 15.27346° | E5: 120.56187° | F5: 79.45 | G5: Silt | H5: ML | I5: 19.8 | K5: 25 | L5: 0.18 | M5: 0.5058 | P5: 17.1-19.2 | Q5: 31-40 | S5: 0.897 | U5: 0.4g | V5: 0.128
A6: Camiling | B6: BH-5 | C6: SS-2 | D6: 15.686632° | E6: 120.412972° | F6: 14.98 | G6: Clayey Silt | H6: MH | I6: 7.6 | J6: 4.5 | K6: 19 | L6: 0.256 | M6: 0.3799 | O6: 4.5 | P6: 10 | Q6: 25 | S6: 0.625 | U6: 0.4g (RP: 500-yr; STIFF Soil) | W6: 15
A7: Camiling | B7: BH-6 | C7: SS-2 | D7: 15.686638° | E7: 120.413130° | F7: 15.28 | G7: Clayey Silt | H7: MH | I7: 7.6 | J7: 5 | K7: 20 | L7: 0.278 | M7: 0.314 | O7: 5 | P7: 10 | Q7: 25 | S7: 0.671 | U7: 0.4g (RP: 500-yr; STIFF Soil) | W7: 15
A8: Camiling | B8: BH-7 | C8: SS-2 | D8: 15.686652° | E8: 120.412968° | F8: 14.67 | G8: Brown, Clayey Silt of medium plasticity | H8: MH | I8: 8.3 | J8: 6 | K8: 13 | L8: 0.266 | M8: 0.3735 | O8: 6 | P8: 20 | Q8: 27.5 | S8: 0.623 | U8: 0.4g | W8: ########
A9: Camiling | B9: BH-8 | C9: SS-2 | D9: 15.686296° | E9: 120.412971° | F9: 15.59 | G9: Brown, Clayey Silt of medium plasticity | H9: MH | I9: 8.3 | J9: 7 | K9: 11 | L9: 0.231 | M9: 0.393 | O9: 7 | P9: 20 | Q9: 27.5 | S9: 0.661 | U9: 0.4g | W9: ########
A10: Camiling | B10: BH-9 | C10: SS-2 | D10: 15.686062° | E10: 120.412563° | F10: 15.59 | G10: Brown, Clayey Silt of medium plasticity | H10: MH | I10: 8.3 | J10: 7 | K10: 13 | L10: 0.261 | M10: 0.3821 | O10: 7 | P10: 20 | Q10: 27.5 | S10: 0.652 | U10: 0.4g | W10: ########
A11: Camiling | B11: BH-10 | C11: SS-2 | D11: 15.732336° | E11: 120.434617° | F11: 9.8 | G11: Clayey Silt | H11: MH | I11: 11.3 | J11: 4.3 | K11: 10 | L11: 0.25 | M11: 0.3549 | N11: 0 | O11: 4.3 | P11: 17 | Q11: 20 | R11: 8 | S11: 0.651 | U11: 0.2g (RP:500-yr; ROCK SITE) | W11: 10
A12: Camiling | B12: BH-11 | C12: SS-2 | D12: 15.743831° | E12: 120.443005° | F12: 24.43 | G12: Sandy Silt | H12: ML | I12: 12.5 | J12: N.E. | K12: 50/15 | L12: 0.132 | M12: 0.2714 | N12: 0 | O12: N.E. | P12: 23 | Q12: 30 | R12: 50/15 | S12: 0.542 | U12: 0.3g (RP:500-yr; STIFF SOIL) (ROCK SITE) | W12: 300
A13: Camiling | B13: BH-12 | C13: SS-2 | D13: 15.743915° | E13: 120.443051° | F13: 25.34 | G13: Sandy Silt | H13: ML | I13: 12.5 | J13: N.E. | K13: 50/15 | L13: 0.161 | M13: 0.223 | N13: 0 | O13: N.E. | P13: 23 | Q13: 30 | R13: 50/15 | S13: 0.562 | U13: 0.3g (RP:500-yr; STIFF SOIL) (ROCK SITE) | W13: 300
A14: Camiling | B14: BH-13 | C14: SS-2 | D14: 15.656521° | E14: 120.400915° | F14: 17.42 | G14: Sandy Silt | H14: ML | I14: 4.8 | J14: 6 | K14: 16 | L14: 0.17 | M14: 0.2445 | O14: 6 | P14: 18 | Q14: 22.5 | R14: 12 | S14: 0.55 | U14: 0.4g | W14: 12
A15: Camiling | B15: BH-14 | C15: SS-2 | D15: 15.645886° | E15: 120.388381° | F15: 32.45 | G15: Gray, Silty Clayey Sand | H15: SC-SM | I15: 3 | J15: 4 | K15: 31 | L15: 0.08 | M15: 0.147 | O15: 4 | P15: 19 | Q15: 32 | S15: 0.1594 | U15: 0.4g | W15: 30
A16: Gerona | B16: BH-15 | C16: SS-2 | D16: 15.635467° | E16: 120.624711° | F16: 22.9 | G16: Silty Sand | H16: SM | I16: 19 | J16: 7.5 | K16: 17 | M16: 0.1967 | N16: 0 | O16: 7.5 | P16: 20 | Q16: 30-32 | R16: 13 | S16: 0.283 | U16: 0.3g (RP: 500-yr; STIFF Soil) | W16: 15000
A17: Gerona | B17: BH-16 | C17: SS-2 | D17: 15.635408° | E17: 120.624588° | F17: 22.29 | G17: Silty Sand | H17: SM | I17: 19 | J17: 7.5 | K17: 16 | M17: 0.2029 | N17: 0 | O17: 7.5 | P17: 20 | Q17: 30-32 | R17: 12 | S17: 0.274 | U17: 0.3g (RP: 500-yr; STIFF Soil) | W17: 15000
A18: Gerona | B18: BH-17 | C18: SS-2 | D18: 15.555744° | E18: 120.600555° | F18: 29.61 | G18: Silty Sand | H18: SM | I18: 11.3 | J18: 3 | K18: 11 | M18: 0.2356 | N18: 0 | O18: 3 | P18: 20 | Q18: 27.5-30 | R18: 8.25 | S18: 0.201 | U18: 0.3g (RP: 500-yr; STIFF Soil) | W18: 10000
A19: Gerona | B19: BH-18 | C19: SS-2 | D19: 15.555718° | E19: 120.600598° | F19: 29.61 | G19: Silty Sand | H19: SM | I19: 11.3 | J19: 3 | K19: 11 | M19: 0.2254 | N19: 0 | O19: 3 | P19: 19 | Q19: 27.5-30 | R19: 8.25 | S19: 0.233 | U19: 0.3g (RP: 500-yr; STIFF Soil) | W19: 10000
A20: Gerona | B20: BH-19 | C20: SS-2 | D20: 15.592509° | E20: 120.620622° | F20: 29.91 | G20: Silty Sand | H20: SM | I20: 15.5 | J20: 3 | K20: 20 | M20: 0.1726 | N20: 0 | O20: 3 | P20: 20 | Q20: 30-32 | R20: 15 | S20: 0.262 | U20: 0.3g (RP: 500-yr; STIFF Soil) | W20: 15000
A21: Gerona | B21: BH-20 | C21: SS-2 | D21: 15.592510° | E21: 120.620552° | F21: 29.9 | G21: Silty Sand | H21: SM | I21: 15.5 | J21: 3 | K21: 21 | M21: 0.1479 | N21: 0 | O21: 3 | P21: 21 | Q21: 30-32 | R21: 16 | S21: 0.247 | U21: 0.3g (RP: 500-yr; STIFF Soil) | W21: 15000
A22: Gerona | B22: BH-21 | C22: SS-2 | D22: 15.556476° | E22: 120.573764° | F22: 29.91 | G22: Silty Sand | H22: SM | I22: 9 | J22: N.E | K22: 11 | M22: 0.1543 | N22: 0 | O22: N.E | P22: 20 | Q22: 27.5-30 | R22: 8 | S22: 0.326 | U22: 0.3g (RP: 500-yr; STIFF Soil) | W22: 10000
A23: Gerona | B23: BH-22 | C23: SS-2 | D23: 15.556501° | E23: 120.573845° | F23: 29.91 | G23: Silty Sand | H23: SM | I23: 9 | J23: N.E | K23: 14 | M23: 0.1977 | N23: 0 | O23: N.E | P23: 19 | Q23: 30-32 | R23: 11 | S23: 0.278 | U23: 0.3g (RP: 500-yr; STIFF Soil) | W23: 15000
A24: Gerona | B24: BH-23 | C24: SS-2 | D24: 15.578777° | E24: 120.573149° | F24: 26.56 | G24: Silty Sand | H24: SM | I24: 11.1 | J24: 12 | K24: 33 | M24: 0.1255 | N24: 0 | O24: 12 | P24: 22 | Q24: 30-32 | R24: 24.75 | S24: 0.3129 | U24: 0.3g (RP: 500-yr; STIFF Soil) | W24: 15000
A25: Gerona | B25: BH-24 | C25: SS-2 | D25: 15.578761° | E25: 120.573483° | F25: 27.48 | G25: Silty Sand | H25: SM | I25: 11.1 | J25: 4.5 | K25: 33 | M25: 0.1707 | N25: 0 | O25: 4.5 | P25: 21 | Q25: 30-32 | R25: 24.75 | S25: 0.2934 | U25: 0.3g (RP: 500-yr; STIFF Soil) | W25: 15000
A26: Gerona | B26: BH-25 | C26: SS-2 | D26: 15.600169° | E26: 120.544751° | F26: 21.07 | G26: Clayey Silt | H26: MH | I26: 11.1 | J26: N.E | K26: 34 | L26: 0.25 | M26: 0.3426 | N26: 0 | O26: N.E | P26: 17 | Q26: 25 | R26: 26 | S26: 0.625 | U26: 0.3g (RP: 500-yr; STIFF Soil) | W26: 15000
A27: Gerona | B27: BH-26 | C27: SS-2 | D27: 15.600168° | E27: 120.544618° | F27: 21.07 | G27: Clayey Silt | H27: MH | I27: 11.1 | J27: N.E | K27: 24 | L27: 0.24 | M27: 0.3571 | N27: 0 | O27: N.E | P27: 17 | Q27: 25 | R27: 18 | S27: 0.639 | U27: 0.3g (RP: 500-yr; STIFF Soil) | W27: 15000
A28: Gerona | B28: BH-27 | C28: SS-2 | D28: 15.589244° | E28: 120.597051° | F28: 27.96 | G28: Silty Sand | H28: SM | I28: 13.3 | J28: 2.5 | K28: 23 | M28: 0.1563 | N28: 0 | O28: 2.5 | P28: 0 | Q28: 30-32 | R28: 17 | S28: 0.291 | U28: 0.3g (RP: 500-yr; STIFF Soil) | W28: 15000
A29: Gerona | B29: BH-28 | C29: SS-2 | D29: 15.58917° | E29: 120.597011° | F29: 27.66 | G29: Silty Sand | H29: SM | I29: 13.3 | J29: 2.5 | K29: 21 | M29: 0.1481 | N29: 0 | O29: 2.5 | P29: 0 | Q29: 30-32 | R29: 16 | S29: 0.286 | U29: 0.3g (RP: 500-yr; STIFF Soil) | W29: 15000
A30: Gerona | B30: BH-29 | C30: SS-2 | D30: 15.620661° | E30: 120.500156° | F30: 28.08 | G30: Sandy Silt | H30: ML | I30: 11 | J30: 3 | K30: 100 | L30: 0.18 | M30: 0.2344 | N30: 0 | O30: 3 | P30: 19 | Q30: 27.5 | R30: 100 | S30: 0.561 | U30: 0.3g (RP: 500-yr; STIFF Soil) | W30: 20000
A31: Gerona | B31: BH-30 | C31: SS-2 | D31: 15.620647° | E31: 120.500056° | F31: 27.17 | G31: Sandy Silt | H31: ML | I31: 11 | J31: 2.37 | K31: 100 | L31: 0.19 | M31: 0.265 | N31: 0 | O31: 2.37 | P31: 18 | Q31: 27.5 | R31: 100 | S31: 0.566 | U31: 0.3g (RP: 500-yr; STIFF Soil) | W31: 20000
A32: Gerona | B32: BH-31 | C32: SS-2 | D32: 15.598641° | E32: 120.517534° | F32: 57.07 | G32: Silty Sand | H32: SM | I32: 10.2 | J32: 7 | K32: 59 | M32: 0.2327 | N32: 0 | O32: 7 | P32: 19 | Q32: 32-35 | R32: 44.25 | S32: 0.35 | U32: 0.3g (RP: 500-yr; STIFF Soil, 0.3g (RP: 500-yr; ROCK Site) | W32: 20000
A33: Gerona | B33: BH-32 | C33: SS-2 | D33: 15.598293° | E33: 120.517626° | F33: 47.88 | G33: Silty Sand | H33: ML | I33: 10.2 | J33: 12 | K33: 55 | L33: 16 | M33: 0.263 | N33: 0 | O33: 12 | P33: 18 | Q33: 27.5 | R33: 41.25 | S33: 0.58 | U33: 0.3g (RP: 500-yr; STIFF Soil, 0.3g (RP: 500-yr; ROCK Site) | W33: 20000
A34: Gerona | B34: BH-33 | C34: SS-2 | D34: 15.555633° | E34: 120.608133° | F34: 29.3 | G34: Silty Clay | H34: CH | I34: 12 | J34: 2 | K34: 10 | L34: 33 | M34: 0.3785 | N34: 0 | O34: 2 | P34: 17 | Q34: 19.5 | R34: 7.5 | S34: 0.85 | U34: 0.3g (RP: 500-yr; STIFF Soil) | W34: 13000
A35: Gerona | B35: BH-34 | C35: SS-2 | D35: 15.555650° | E35: 120.608052° | F35: 29.3 | G35: Silty Clay | H35: CH | I35: 12 | J35: 2 | K35: 10 | L35: 32 | M35: 0.4527 | N35: 0 | O35: 2 | P35: 16 | Q35: 19.5 | R35: 7.5 | S35: 0.87 | U35: 0.3g (RP: 500-yr; STIFF Soil) | W35: 13000
A36: Gerona | B36: BH-35 | C36: SS-2 | D36: 15.602424° | E36: 120.593012° | F36: 30.52 | G36: Silty Sand | H36: SM | I36: 11.1 | J36: 4.5 | K36: 39 | M36: 0.161 | N36: 0 | O36: 4.5 | P36: 21 | Q36: 32-35 | R36: 29 | S36: 0.284 | U36: 0.3g (RP: 500-yr; STIFF Soil) | W36: 20000
A37: Gerona | B37: BH-36 | C37: SS-2 | D37: 15.602593° | E37: 120.593001° | F37: 31.13 | G37: Silty Sand | H37: SM | I37: 11.1 | J37: 4.5 | K37: 22 | M37: 0.1704 | N37: 0 | O37: 4.5 | P37: 0 | Q37: 30-32 | R37: 17 | S37: 0.242 | U37: 0.3g (RP: 500-yr; STIFF Soil) | W37: 15000
A38: Moncada | B38: BH-37 | C38: SS-2 | D38: 15.745085° | E38: 120.576019° | F38: 20.8 | G38: Sandy Silt | H38: ML | I38: 26.5 | J38: 2 | K38: 15 | L38: 0.15 | M38: 0.2647 | O38: 2 | P38: 20 | Q38: 27.5 | S38: 0.56 | U38: 0.3g | W38: ########
A39: Moncada | B39: BH-38 | C39: SS-2 | D39: 15.744907° | E39: 120.576261° | F39: 21.7 | G39: Sandy Silt | H39: ML | I39: 26.5 | J39: 2 | K39: 18 | L39: 0.2 | M39: 0.2698 | O39: 2 | P39: 21 | Q39: 27.5 | S39: 0.54 | U39: 0.3g | W39: 15-40
A40: Moncada | B40: BH-39 | C40: SS-2 | D40: 15.769566° | E40: 120.575766° | F40: 18.9 | G40: Sandy Silt | H40: ML | I40: 27 | J40: 1.05 | K40: 17 | L40: 0.1645 | M40: 0.2952 | O40: 1.05 | P40: 21 | Q40: 27.5 | S40: 0.5161 | W40: 15-40
...

Sheet 3.0m-4.5m
A1: Municipality | B1: Borehole ID | C1: Sample No. | D1: Latitude | E1: Longitude | F1: Elevation | G1: Soil/Rock Description | H1: USCS Symbol | I1: Fault Distance (km) | J1: Ground Water Table | K1: SPT N-Value | L1: Plasticity Index (PI) | M1: Natural Water Content (ω) | N1: Mean Particle Size (D50) (mm) | O1: Groundwater Level (m) | P1: Unit Weight (γ) | Q1: Foundation Width (B) | R1: Foundation Depth (D) | S1: Internal Friction Angle | T1: Length-to-width ratio (L/B) | U1: Corrected SPT-N Value (N1(60)) | V1: Fines Content | W1: Effective Overburden Presssure | X1: Total Overburden Pressure | Y1: Relative Density | Z1: Peak Ground Acceleration | AA1: Cyclic Stress Ratio (CSR) | AB1: Elastic Modulus (Es) (MN/
B2: BH-1
B3: BH-2
B4: BH-3
B5: BH-4
B6: BH-5
B7: BH-6
B8: BH-7
B9: BH-8
B10: BH-9
B11: BH-10
B12: BH-11
B13: BH-12
... B103: BH-102

Sheet 4.5m-6.0m
A1: Municipality | B1: Borehole ID | C1: Sample No. | D1: Latitude | E1: Longitude | F1: Elevation | G1: Soil/Rock Description | H1: USCS Symbol | I1: Fault Distance (km) | J1: Ground Water Table | K1: SPT N-Value | L1: Plasticity Index (PI) | M1: Natural Water Content (ω) | N1: Mean Particle Size (D50) (mm) | O1: Groundwater Level (m) | P1: Unit Weight (γ) | Q1: Foundation Width (B) | R1: Foundation Depth (D) | S1: Internal Friction Angle | T1: Length-to-width ratio (L/B) | U1: Corrected SPT-N Value (N1(60)) | V1: Fines Content | W1: Effective Overburden Presssure | X1: Total Overburden Pressure | Y1: Relative Density | Z1: Peak Ground Acceleration | AA1: Cyclic Stress Ratio (CSR) | AB1: Elastic Modulus (Es) (MN/
A2: Anao | B2: BH-1 | C2: SS-4 | D2: 15.715506° | E2: 120.623904° | F2: 12.28 | G2: Sandy Silt | H2: ML | I2: 26.3 | J2: 28.5 | K2: 12 | L2: 0.1691 | M2: 0.2264 | N2: 16.91 | O2: 28.5 | P2: 20 | Q2: 27.5 | R2: 9 | S2: 0.5722 | U2: 0.4g (RP: 500-yr; STIFF Soil) | W2: 10000 to 30000
A3: Anao | B3: BH-2 | C3: SS-4 | D3: 15.759126° | E3: 120.600236° | F3: 22.65 | G3: Silty Clay | H3: CH | I3: 30.8 | J3: 1.5 | K3: 19 | L3: 0.3525 | M3: 0.3262 | N3: 0 | O3: 1.5 | P3: 17 | Q3: 20 | R3: 14.25 | S3: 0.8638 | U3: 0.3g (RP: 500-yr; STIFF Soil) | W3: 25000
A4: Anao | B4: BH-3 | C4: SS-4 | D4: 15.759537° | E4: 120.600182° | F4: 18.99 | G4: Silty Sand | H4: SM | I4: 30.8 | J4: 1.5 | K4: 17 | M4: 0.1859 | N4: 0 | O4: 1.5 | P4: 21 | Q4: 30 | R4: 12.75 | S4: 0.2697 | U4: 0.3g (RP: 500-yr; STIFF Soil) | W4: 15000
A5: Bamban | B5: BH-4 | C5: SS-4 | D5: 15.27346° | E5: 120.56187° | F5: 76.95 | G5: Silt | H5: ML | I5: 19.8 | K5: 39 | L5: 0.17 | M5: 0.5345 | P5: 17.1-19.2 | Q5: 31-40 | S5: 0.89 | U5: 0.4g | V5: 0.126
A6: Camiling | B6: BH-5 | C6: SS-4 | D6: 15.686632° | E6: 120.412972° | F6: 11.98 | G6: Clayey Silt | H6: MH | I6: 7.6 | J6: 4.5 | K6: 28 | L6: 0.233 | M6: 0.3853 | O6: 4.5 | P6: 16.6 | Q6: 25 | S6: 0.672 | U6: 0.4g (RP: 500-yr; STIFF Soil) | W6: 15
A7: Camiling | B7: BH-6 | C7: SS-4 | D7: 15.686638° | E7: 120.413130° | F7: 12.28 | G7: Clayey Silt | H7: MH | I7: 7.6 | J7: 5 | K7: 26 | L7: 0.264 | M7: 0.3857 | O7: 5 | P7: 16.8 | Q7: 25 | S7: 0.639 | U7: 0.4g (RP: 500-yr; STIFF Soil) | W7: 15
A8: Camiling | B8: BH-7 | C8: SS-4 | D8: 15.686652° | E8: 120.412968° | F8: 11.67 | G8: Brown, Clayey Silt of medium plasticity | H8: MH | I8: 8.3 | J8: 6 | K8: 15 | L8: 0.24 | M8: 0.3658 | O8: 6 | P8: 20 | Q8: 27.5 | S8: 0.643 | U8: 0.4g | W8: ########
A9: Camiling | B9: BH-8 | C9: SS-4 | D9: 15.686296° | E9: 120.412971° | F9: 12.59 | G9: Brown, Clayey Silt of medium plasticity | H9: MH | I9: 8.3 | J9: 7 | K9: 13 | L9: 0.22 | M9: 0.2721 | O9: 7 | P9: 20 | Q9: 27.5 | S9: 0.682 | U9: 0.4g | W9: ########
A10: Camiling | B10: BH-9 | C10: SS-4 | D10: 15.686062° | E10: 120.412563° | F10: 12.59 | G10: Brown, Clayey Silt of medium plasticity | H10: MH | I10: 8.3 | J10: 7 | K10: 6 | L10: 0.243 | M10: 0.3529 | O10: 7 | P10: 20 | Q10: 27.5 | S10: 0.672 | U10: 0.4g | W10: ########
A11: Camiling | B11: BH-10 | C11: SS-4 | D11: 15.732336° | E11: 120.434617° | F11: 6.8 | G11: Clayey Silt | H11: MH | I11: 11.3 | J11: 4.3 | K11: 15 | L11: 0.254 | M11: 0.3432 | N11: 0 | O11: 4.3 | P11: 17 | Q11: 22.5 | R11: 11 | S11: 0.668 | U11: 0.2g (RP:500-yr; ROCK SITE) | W11: 12
A12: Gerona | B12: BH-11 | C12: SS-4 | D12: 15.635467° | E12: 120.624711° | F12: 19.9 | G12: Clayey Silt | H12: MH | I12: 19 | J12: 7.5 | K12: 29 | L12: 0.271 | M12: 0.3909 | N12: 0 | O12: 7.5 | P12: 17 | Q12: 25 | R12: 22 | S12: 0.613 | U12: 0.3g (RP: 500-yr; STIFF Soil) | W12: 15000
A13: Gerona | B13: BH-12 | C13: SS-4 | D13: 15.635408° | E13: 120.624588° | F13: 19.29 | G13: Clayey Silt | H13: MH | I13: 19 | J13: 7.5 | K13: 29 | L13: 0.268 | M13: 0.361 | N13: 0 | O13: 7.5 | P13: 17 | Q13: 25 | R13: 22 | S13: 0.642 | U13: 0.3g (RP: 500-yr; STIFF Soil) | W13: 15000
A14: Gerona | B14: BH-13 | C14: SS-4 | D14: 15.555744° | E14: 120.600555° | F14: 26.61 | G14: Silty Sand | H14: SM | I14: 11.3 | J14: 3 | K14: 26 | M14: 0.2138 | N14: 0 | O14: 3 | P14: 0 | Q14: 30-32 | R14: 19.5 | S14: 0.246 | U14: 0.3g (RP: 500-yr; STIFF Soil) | W14: 15000
A15: Gerona | B15: BH-14 | C15: SS-4 | D15: 15.555718° | E15: 120.600598° | F15: 26.61 | G15: Silty Sand | H15: SM | I15: 11.3 | J15: 3 | K15: 18 | M15: 0.2091 | N15: 0 | O15: 3 | P15: 20 | Q15: 30-32 | R15: 13.5 | S15: 0.244 | U15: 0.3g (RP: 500-yr; STIFF Soil) | W15: 15000
A16: Gerona | B16: BH-15 | C16: SS-4 | D16: 15.592509° | E16: 120.620622° | F16: 26.91 | G16: Silty Sand | H16: SM | I16: 15.5 | J16: 3 | K16: 38 | M16: 0.1426 | N16: 0 | O16: 3 | P16: 21 | Q16: 32-35 | R16: 29 | S16: 0.239 | U16: 0.3g (RP: 500-yr; STIFF Soil) | W16: 20000
A17: Gerona | B17: BH-16 | C17: SS-4 | D17: 15.592510° | E17: 120.620552° | F17: 26.9 | G17: Silty Sand | H17: SM | I17: 15.5 | J17: 3 | K17: 24 | M17: 0.1728 | N17: 0 | O17: 3 | P17: 20 | Q17: 30-32 | R17: 18 | S17: 0.285 | U17: 0.3g (RP: 500-yr; STIFF Soil) | W17: 15000
A18: Gerona | B18: BH-17 | C18: SS-4 | D18: 15.556476° | E18: 120.573764° | F18: 26.91 | G18: Silty Sand | H18: SM | I18: 9 | J18: N.E | K18: 24 | M18: 0.1652 | N18: 0 | O18: N.E | P18: 19 | Q18: 30-32 | R18: 18 | S18: 0.239 | U18: 0.3g (RP: 500-yr; STIFF Soil) | W18: 15000
A19: Gerona | B19: BH-18 | C19: SS-4 | D19: 15.556501° | E19: 120.573845° | F19: 26.91 | G19: Silty Sand | H19: SM | I19: 9 | J19: N.E | K19: 28 | M19: 0.1675 | N19: 0 | O19: N.E | P19: 19 | Q19: 30-32 | R19: 21 | S19: 0.248 | U19: 0.3g (RP: 500-yr; STIFF Soil) | W19: 15000
A20: Gerona | B20: BH-19 | C20: SS-4 | D20: 15.578777° | E20: 120.573149° | F20: 23.56 | G20: Clayey Silt | H20: MH | I20: 11.1 | J20: 12 | K20: 12 | L20: 0.2267 | M20: 0.3524 | N20: 0 | O20: 12 | P20: 17 | Q20: 22.5 | R20: 9 | S20: 0.624 | U20: 0.3g (RP: 500-yr; STIFF Soil) | W20: 12000
A21: Gerona | B21: BH-20 | C21: SS-4 | D21: 15.578761° | E21: 120.573483° | F21: 24.48 | G21: Clayey Silt | H21: MH | I21: 11.1 | J21: 4.5 | K21: 13 | L21: 0.2331 | M21: 0.3312 | N21: 0 | O21: 4.5 | P21: 17 | Q21: 22.5 | R21: 9.75 | S21: 0.6302 | U21: 0.3g (RP: 500-yr; STIFF Soil) | W21: 12000
A22: Gerona | B22: BH-21 | C22: SS-4 | D22: 15.600169° | E22: 120.544751° | F22: 18.07 | G22: Clayey Silt | H22: MH | I22: 11.1 | J22: N.E | K22: 36 | L22: 0.27 | M22: 0.3427 | N22: 0 | O22: N.E | P22: 17 | Q22: 25 | R22: 27 | S22: 0.627 | U22: 0.3g (RP: 500-yr; STIFF Soil) | W22: 15000
A23: Gerona | B23: BH-22 | C23: SS-4 | D23: 15.600168° | E23: 120.544618° | F23: 18.07 | G23: Clayey Silt | H23: MH | I23: 11.1 | J23: N.E | K23: 31 | L23: 0.26 | M23: 0.3415 | N23: 0 | O23: N.E | P23: 17 | Q23: 25 | R23: 23 | S23: 0.639 | U23: 0.3g (RP: 500-yr; STIFF Soil) | W23: 15000
A24: Gerona | B24: BH-23 | C24: SS-4 | D24: 15.589244° | E24: 120.597051° | F24: 24.96 | G24: Silty Sand | H24: SM | I24: 13.3 | J24: 2.5 | K24: 37 | M24: 0.1508 | N24: 0 | O24: 2.5 | P24: 21 | Q24: 32-35 | R24: 28 | S24: 0.261 | U24: 0.3g (RP: 500-yr; STIFF Soil) | W24: 20000
A25: Gerona | B25: BH-24 | C25: SS-4 | D25: 15.58917° | E25: 120.597011° | F25: 24.66 | G25: Silty Sand | H25: SM | I25: 13.3 | J25: 2.5 | K25: 42 | M25: 0.1582 | N25: 0 | O25: 2.5 | P25: 21 | Q25: 32-35 | R25: 32 | S25: 0.271 | U25: 0.3g (RP: 500-yr; STIFF Soil) | W25: 20000
A26: Gerona | B26: BH-25 | C26: SS-4 | D26: 15.598641° | E26: 120.517534° | F26: 54.07 | G26: Sandy Silt | H26: ML | I26: 10.2 | J26: 7 | K26: 87 | L26: 15 | M26: 0.2199 | N26: 0 | O26: 7 | P26: 21 | Q26: 27.5 | R26: 65.25 | S26: 0.54 | U26: 0.3g (RP: 500-yr; STIFF Soil, 0.3g (RP: 500-yr; ROCK Site) | W26: 20000
A27: Gerona | B27: BH-26 | C27: SS-4 | D27: 15.598293° | E27: 120.517626° | F27: 44.78 | G27: Sandy Silt | H27: SM | I27: 10.2 | J27: 12 | K27: 96 | M27: 0.3454 | N27: 0 | O27: 12 | P27: 18 | Q27: 35-37 | R27: 72 | S27: 0.63 | U27: 0.3g (RP: 500-yr; STIFF Soil, 0.3g (RP: 500-yr; ROCK Site) | W27: 25000
A28: Gerona | B28: BH-27 | C28: SS-4 | D28: 15.555633° | E28: 120.608133° | F28: 26.3 | G28: Silty Clay | H28: CH | I28: 12 | J28: 2 | K28: 18 | L28: 35 | M28: 0.4247 | N28: 0 | O28: 2 | P28: 16 | Q28: 20 | R28: 13.5 | S28: 0.84 | U28: 0.3g (RP: 500-yr; STIFF Soil) | W28: 25000
A29: Gerona | B29: BH-28 | C29: SS-4 | D29: 15.555650° | E29: 120.608052° | F29: 26.3 | G29: Silty Clay | H29: CH | I29: 12 | J29: 2 | K29: 12 | L29: 36 | M29: 0.3545 | N29: 0 | O29: 2 | P29: 17 | Q29: 20 | R29: 9 | S29: 0.82 | U29: 0.3g (RP: 500-yr; STIFF Soil) | W29: 25000
A30: Gerona | B30: BH-29 | C30: SS-2 | D30: 15.596727° | E30: 120.608189° | F30: 27.22 | G30: Silty Clay | H30: CH | I30: 24.2 | J30: 1.5 | K30: 16 | L30: 35.4 | M30: 0.3641 | N30: 0 | O30: 1.5 | P30: 17 | Q30: 20 | R30: 12 | S30: 0.838 | U30: 0.3g (RP: 500-yr; STIFF Soil) | W30: 25000
A31: Gerona | B31: BH-30 | C31: SS-4 | D31: 15.602424° | E31: 120.593012° | F31: 27.52 | G31: Silty Sand | H31: SM | I31: 11.1 | J31: 4.5 | K31: 44 | M31: 0.138 | N31: 0 | O31: 4.5 | P31: 21 | Q31: 32-35 | R31: 33 | S31: 0.307 | U31: 0.3g (RP: 500-yr; STIFF Soil) | W31: 20000
A32: Gerona | B32: BH-31 | C32: SS-4 | D32: 15.602593° | E32: 120.593001° | F32: 28.13 | G32: Silty Sand | H32: SM | I32: 11.1 | J32: 4.5 | K32: 46 | M32: 0.1727 | N32: 0 | O32: 4.5 | P32: 0 | Q32: 32-35 | R32: 35 | S32: 0.227 | U32: 0.3g (RP: 500-yr; STIFF Soil) | W32: 20000
A33: Moncada | B33: BH-32 | C33: SS-4 | D33: 15.745085° | E33: 120.576019° | F33: 17.8 | G33: Sandy Silt | H33: ML | I33: 26.5 | J33: 2 | K33: 27 | L33: 0.16 | M33: 0.2469 | O33: 2 | P33: 21 | Q33: 27.5 | S33: 0.58 | U33: 0.3g | W33: 15-40
A34: Moncada | B34: BH-33 | C34: SS-4 | D34: 15.744907° | E34: 120.576261° | F34: 18.7 | G34: Sandy Silt | H34: ML | I34: 26.5 | J34: 2 | K34: 25 | L34: 0.19 | M34: 0.2359 | O34: 2 | P34: 21 | Q34: 27.5 | S34: 0.52 | U34: 0.3g | W34: 15-40
A35: Moncada | B35: BH-34 | C35: SS-4 | D35: 15.769566° | E35: 120.575766° | F35: 15.9 | G35: Silty Sand | H35: SM | I35: 27 | J35: 1.05 | K35: 14 | M35: 0.1822 | O35: 1.05 | P35: 20 | Q35: 32.5 | S35: 0.3109 | W35: 15-50
A36: Moncada | B36: BH-35 | C36: SS-4 | D36: 15.769692° | E36: 120.575525° | F36: 15.3 | G36: Sandy Silt | H36: ML | I36: 27 | J36: 1 | K36: 32 | L36: 0.1771 | M36: 0.2731 | O36: 1 | P36: 21 | Q36: 27.5 | S36: 0.5566 | W36: 30-80
A37: Moncada | B37: BH-36 | C37: SS-4 | D37: 15.808724° | E37: 120.571566° | F37: 17.2 | G37: Sandy Silt | H37: ML | I37: 28.5 | J37: 1 | K37: 23 | L37: 0.131 | M37: 0.2598 | O37: 1 | P37: 21 | Q37: 27.5 | S37: 0.522 | W37: 15-40
A38: Moncada | B38: BH-37 | C38: SS-4 | D38: 15.808848° | E38: 120.571571° | F38: 17.2 | G38: Sandy Silt | H38: ML | I38: 28.5 | J38: 1 | K38: 25 | L38: 0.15 | M38: 0.2415 | O38: 1 | P38: 21 | Q38: 27.5 | S38: 0.561 | W38: 15-40
A39: Moncada | B39: BH-38 | C39: SS-4 | D39: 15.737812° | E39: 120.577325° | F39: 249.9 | G39: Sandy Silt | H39: ML | I39: 26.1 | J39: 6 | K39: 13 | L39: 0.1446 | M39: 0.2748 | O39: 6 | P39: 20 | Q39: 27.5 | S39: 0.5213 | W39: ########
A40: Moncada | B40: BH-39 | C40: SS-4 | D40: 15.737879° | E40: 120.577483° | F40: 249.9 | G40: Sandy Silt | H40: ML | I40: 26.1 | J40: 6 | K40: 14 | L40: 0.1576 | M40: 0.2333 | O40: 6 | P40: 20 | Q40: 27.5 | S40: 0.5694 | W40: ########
...

Sheet 6.0m-7.5m
A1: Municipality | B1: Borehole ID | C1: Sample No. | D1: Latitude | E1: Longitude | F1: Elevation | G1: Soil/Rock Description | H1: USCS Symbol | I1: Fault Distance (km) | J1: Ground Water Table | K1: SPT N-Value | L1: Plasticity Index (PI) | M1: Natural Water Content (ω) | N1: Mean Particle Size (D50) (mm) | O1: Groundwater Level (m) | P1: Unit Weight (γ) | Q1: Foundation Width (B) | R1: Foundation Depth (D) | S1: Internal Friction Angle | T1: Length-to-width ratio (L/B) | U1: Corrected SPT-N Value (N1(60)) | V1: Fines Content | W1: Effective Overburden Presssure | X1: Total Overburden Pressure | Y1: Relative Density | Z1: Peak Ground Acceleration | AA1: Cyclic Stress Ratio (CSR) | AB1: Elastic Modulus (Es) (MN/
A2: Anao | B2: BH-1 | C2: SS-5 | D2: 15.715506° | E2: 120.623904° | F2: 10.78 | G2: Sandy Silt | H2: ML | I2: 26.3 | J2: 28.5 | K2: 16 | L2: 0.1659 | M2: 0.2878 | N2: 16.59 | O2: 28.5 | P2: 20 | Q2: 27.5 | R2: 12 | S2: 0.543 | U2: 0.4g (RP: 500-yr; STIFF Soil) | W2: 10000 to 30000
A3: Anao | B3: BH-2 | C3: SS-5 | D3: 15.759126° | E3: 120.600236° | F3: 21.15 | G3: Silty Sand | H3: SM | I3: 30.8 | J3: 1.5 | K3: 24 | M3: 0.1841 | N3: 0 | O3: 1.5 | P3: 20 | Q3: 30 | R3: 18 | S3: 0.3112 | U3: 0.3g (RP: 500-yr; STIFF Soil) | W3: 15000
A4: Anao | B4: BH-3 | C4: SS-5 | D4: 15.759537° | E4: 120.600182° | F4: 20.49 | G4: Silty Sand | H4: SM | I4: 30.8 | J4: 1.5 | K4: 19 | M4: 0.2438 | N4: 0 | O4: 1.5 | P4: 20 | Q4: 30 | R4: 14.25 | S4: 0.2643 | U4: 0.3g (RP: 500-yr; STIFF Soil) | W4: 15000
A5: Bamban | B5: BH-4 | C5: SS-5 | D5: 15.27346° | E5: 120.56187° | F5: 75.45 | G5: Sandy Lean Clay | H5: CL | I5: 19.8 | K5: 57 | L5: 0.14 | M5: 0.3604 | P5: 17.1-19.2 | Q5: 31-40 | S5: 0.62 | U5: 0.4g | V5: 0.125
A6: Camiling | B6: BH-5 | C6: SS-5 | D6: 15.686632° | E6: 120.412972° | F6: 10.48 | G6: Clayey Silt | H6: MH | I6: 7.6 | J6: 4.5 | K6: 27 | L6: 0.274 | M6: 0.3735 | O6: 4.5 | P6: 16.7 | Q6: 25 | S6: 0.638 | U6: 0.4g (RP: 500-yr; STIFF Soil) | W6: 15
A7: Camiling | B7: BH-6 | C7: SS-5 | D7: 15.686638° | E7: 120.413130° | F7: 10.78 | G7: Clayey Silt | H7: MH | I7: 7.6 | J7: 5 | K7: 35 | L7: 0.248 | M7: 0.3297 | O7: 5 | P7: 17.3 | Q7: 27.5 | S7: 0.672 | U7: 0.4g (RP: 500-yr; STIFF Soil) | W7: 20
A8: Camiling | B8: BH-7 | C8: SS-5 | D8: 15.686652° | E8: 120.412968° | F8: 10.17 | G8: Brown, Clayey Silt of medium plasticity | H8: MH | I8: 8.3 | J8: 6 | K8: 16 | L8: 0.26 | M8: 0.3329 | O8: 6 | P8: 21 | Q8: 27.5 | S8: 0.677 | U8: 0.4g | W8: 15-40
A9: Camiling | B9: BH-8 | C9: SS-5 | D9: 15.686296° | E9: 120.412971° | F9: 11.09 | G9: Brown, Clayey Silt of medium plasticity | H9: MH | I9: 8.3 | J9: 7 | K9: 21 | L9: 0.267 | M9: 0.3523 | O9: 7 | P9: 21 | Q9: 27.5 | S9: 0.67 | U9: 0.4g | W9: 15-40
